Workbook
Name Producto: 'Costo Materia Prima'!$D$3:$D$181

Sheet Precios Mayoreo
J1: Precio Sugerido Venta al Público | Q1: Precio Sugerido Venta a Mayoreo
C2: Presentación de Sub-producto | J2: 0.45 | Q2: 0.05
A3: Producto | B3: Sub-producto | C3: Individual | D3: Mini | E3: Chico | F3: Mediano | G3: Grande | H3: Rebanada | J3: Individual | K3: Mini | L3: Chico | M3: Mediano | N3: Grande | O3: Rebanada | Q3: Individual | R3: Mini | S3: Chico | T3: Mediano | U3: Grande | V3: Rebanada
A4: Pay | B4: Fresa | C4: =Pay!C53 -> 18.916121 | D4: 0 | E4: 0 | F4: =Pay!D53 -> 140.58423 | G4: =Pay!E53 -> 240.03393 | H4: =Pay!F53 -> 32.704881 | J4: =C4/$J$2 -> 42.035824 | K4: =D4/$J$2 -> 0 | L4: =E4/$J$2 -> 0 | M4: =F4/$J$2 -> 312.4094 | N4: =G4/$J$2 -> 533.40873 | O4: =H4/$J$2 -> 72.677513 | Q4: =J4*(1-$Q$2) -> 39.934033 | R4: =K4*(1-$Q$2) -> 0 | S4: =L4*(1-$Q$2) -> 0 | T4: =M4*(1-$Q$2) -> 296.78893 | U4: =N4*(1-$Q$2) -> 506.73829 | V4: =O4*(1-$Q$2) -> 69.043637
B5: Guayaba | C5: =Pay!C54 -> 19.055935 | D5: 0 | E5: 0 | F5: =Pay!D54 -> 148.26907 | G5: =Pay!E54 -> 240.58042 | H5: =Pay!F54 -> 32.773193 | J5: =C5/$J$2 -> 42.346523 | K5: =D5/$J$2 -> 0 | L5: =E5/$J$2 -> 0 | M5: =F5/$J$2 -> 329.48683 | N5: =G5/$J$2 -> 534.62316 | O5: =H5/$J$2 -> 72.829317 | Q5: =J5*(1-$Q$2) -> 40.229197 | R5: =K5*(1-$Q$2) -> 0 | S5: =L5*(1-$Q$2) -> 0 | T5: =M5*(1-$Q$2) -> 313.01249 | U5: =N5*(1-$Q$2) -> 507.892 | V5: =O5*(1-$Q$2) -> 69.187851
B6: Galleta con cajeta | C6: =Pay!C55 -> 20.11006 | D6: 0 | E6: 0 | F6: =Pay!D55 -> 135.33744 | G6: =Pay!E55 -> 229.02898 | H6: =Pay!F55 -> 31.329262 | J6: =C6/$J$2 -> 44.689022 | K6: =D6/$J$2 -> 0 | L6: =E6/$J$2 -> 0 | M6: =F6/$J$2 -> 300.74987 | N6: =G6/$J$2 -> 508.95328 | O6: =H6/$J$2 -> 69.620583 | Q6: =J6*(1-$Q$2) -> 42.454571 | R6: =K6*(1-$Q$2) -> 0 | S6: =L6*(1-$Q$2) -> 0 | T6: =M6*(1-$Q$2) -> 285.71238 | U6: =N6*(1-$Q$2) -> 483.50562 | V6: =O6*(1-$Q$2) -> 66.139553
B7: Oreo | C7: =Pay!C57 -> 18.623235 | D7: 0 | E7: 0 | F7: =Pay!D57 -> 139.81162 | G7: =Pay!E57 -> 238.53794 | H7: =Pay!F57 -> 32.517883 | J7: =C7/$J$2 -> 41.384968 | K7: =D7/$J$2 -> 0 | L7: =E7/$J$2 -> 0 | M7: =F7/$J$2 -> 310.69249 | N7: =G7/$J$2 -> 530.08432 | O7: =H7/$J$2 -> 72.261962 | Q7: =J7*(1-$Q$2) -> 39.315719 | R7: =K7*(1-$Q$2) -> 0 | S7: =L7*(1-$Q$2) -> 0 | T7: =M7*(1-$Q$2) -> 295.15787 | U7: =N7*(1-$Q$2) -> 503.5801 | V7: =O7*(1-$Q$2) -> 68.648864
B8: Pay horneado | C8: =Pay!C58 -> 0 | D8: 0 | E8: 0 | F8: =Pay!D58 -> 86.851881 | G8: =Pay!E58 -> 148.87704 | H8: =Pay!F58 -> 21.310271 | J8: =C8/$J$2 -> 0 | K8: =D8/$J$2 -> 0 | L8: =E8/$J$2 -> 0 | M8: =F8/$J$2 -> 193.00418 | N8: =G8/$J$2 -> 330.83788 | O8: =H8/$J$2 -> 47.356157 | Q8: =J8*(1-$Q$2) -> 0 | R8: =K8*(1-$Q$2) -> 0 | S8: =L8*(1-$Q$2) -> 0 | T8: =M8*(1-$Q$2) -> 183.35397 | U8: =N8*(1-$Q$2) -> 314.29598 | V8: =O8*(1-$Q$2) -> 44.988349
B9: Pay de queso | C9: =Pay!C59 -> 0 | D9: 0 | E9: 0 | F9: =Pay!D59 -> 115.18762 | G9: =Pay!E59 -> 195.44594 | H9: =Pay!F59 -> 27.131383 | J9: =C9/$J$2 -> 0 | K9: =D9/$J$2 -> 0 | L9: =E9/$J$2 -> 0 | M9: =F9/$J$2 -> 255.97249 | N9: =G9/$J$2 -> 434.32432 | O9: =H9/$J$2 -> 60.291962 | Q9: =J9*(1-$Q$2) -> 0 | R9: =K9*(1-$Q$2) -> 0 | S9: =L9*(1-$Q$2) -> 0 | T9: =M9*(1-$Q$2) -> 243.17387 | U9: =N9*(1-$Q$2) -> 412.6081 | V9: =O9*(1-$Q$2) -> 57.277364
A10: Pastel | B10: Fresas con Crema | C10: ='Pastel Fresas Con Crema'!D12 -> 0 | D10: ='Pastel Fresas Con Crema'!E12 -> 77.965623 | E10: ='Pastel Fresas Con Crema'!F12 -> 149.6192 | F10: ='Pastel Fresas Con Crema'!G12 -> 210.11335 | G10: ='Pastel Fresas Con Crema'!H12 -> 338.61711 | H10: ='Pastel Fresas Con Crema'!C12 -> 23.818475 | J10: =C10/$J$2 -> 0 | K10: =D10/$J$2 -> 173.25694 | L10: =E10/$J$2 -> 332.48712 | M10: =F10/$J$2 -> 466.91855 | N10: =G10/$J$2 -> 752.48247 | O10: =H10/$J$2 -> 52.929944 | Q10: =J10*(1-$Q$2) -> 0 | R10: =K10*(1-$Q$2) -> 164.59409 | S10: =L10*(1-$Q$2) -> 315.86276 | T10: =M10*(1-$Q$2) -> 443.57263 | U10: =N10*(1-$Q$2) -> 714.85835 | V10: =O10*(1-$Q$2) -> 50.283447
B11: 3 Pecados | C11: 0 | D11: ='Pastel 3 Pecados'!E18 -> 64.125646 | E11: ='Pastel 3 Pecados'!F18 -> 163.26597 | F11: ='Pastel 3 Pecados'!G18 -> 234.88562 | G11: ='Pastel 3 Pecados'!H18 -> 350.57494 | H11: ='Pastel 3 Pecados'!C18 -> 26.295702 | J11: =C11/$J$2 -> 0 | K11: =D11/$J$2 -> 142.50144 | L11: =E11/$J$2 -> 362.81327 | M11: =F11/$J$2 -> 521.96804 | N11: =G11/$J$2 -> 779.05543 | O11: =H11/$J$2 -> 58.434893 | Q11: =J11*(1-$Q$2) -> 0 | R11: =K11*(1-$Q$2) -> 135.37636 | S11: =L11*(1-$Q$2) -> 344.67261 | T11: =M11*(1-$Q$2) -> 495.86964 | U11: =N11*(1-$Q$2) -> 740.10266 | V11: =O11*(1-$Q$2) -> 55.513149
B12: Zanahoria | C12: 0 | D12: 0 | E12: ='Pastel Zanahoria'!F12 -> 151.95679 | F12: ='Pastel Zanahoria'!G12 -> 207.49008 | G12: ='Pastel Zanahoria'!H12 -> 317.43002 | H12: ='Pastel Zanahoria'!C12 -> 23.556148 | J12: =C12/$J$2 -> 0 | K12: =D12/$J$2 -> 0 | L12: =E12/$J$2 -> 337.68175 | M12: =F12/$J$2 -> 461.08908 | N12: =G12/$J$2 -> 705.40005 | O12: =H12/$J$2 -> 52.346997 | Q12: =J12*(1-$Q$2) -> 0 | R12: =K12*(1-$Q$2) -> 0 | S12: =L12*(1-$Q$2) -> 320.79766 | T12: =M12*(1-$Q$2) -> 438.03462 | U12: =N12*(1-$Q$2) -> 670.13005 | V12: =O12*(1-$Q$2) -> 49.729647
B13: Chocolate | C13: 0 | D13: ='Pastel Chocolate'!E12 -> 59.756374 | E13: 0 | F13: 0 | G13: 0 | H13: 0 | J13: =C13/$J$2 -> 0 | K13: =D13/$J$2 -> 132.79194 | L13: =E13/$J$2 -> 0 | M13: =F13/$J$2 -> 0 | N13: =G13/$J$2 -> 0 | O13: =H13/$J$2 -> 0 | Q13: =J13*(1-$Q$2) -> 0 | R13: =K13*(1-$Q$2) -> 126.15235 | S13: =L13*(1-$Q$2) -> 0 | T13: =M13*(1-$Q$2) -> 0 | U13: =N13*(1-$Q$2) -> 0 | V13: =O13*(1-$Q$2) -> 0
B14: Crunch | C14: 0 | D14: ='Pastel Crunch'!E14 -> 80.227256 | E14: ='Pastel Crunch'!F14 -> 166.4893 | F14: ='Pastel Crunch'!G14 -> 242.04424 | G14: ='Pastel Crunch'!H14 -> 338.62657 | H14: ='Pastel Crunch'!C14 -> 27.011564 | J14: =C14/$J$2 -> 0 | K14: =D14/$J$2 -> 178.28279 | L14: =E14/$J$2 -> 369.97623 | M14: =F14/$J$2 -> 537.87609 | N14: =G14/$J$2 -> 752.50349 | O14: =H14/$J$2 -> 60.025697 | Q14: =J14*(1-$Q$2) -> 0 | R14: =K14*(1-$Q$2) -> 169.36865 | S14: =L14*(1-$Q$2) -> 351.47742 | T14: =M14*(1-$Q$2) -> 510.98228 | U14: =N14*(1-$Q$2) -> 714.87832 | V14: =O14*(1-$Q$2) -> 57.024413
B15: Snicker's | C15: 0 | D15: ='Pastel Snicker''s'!E14 -> 33.131041 | E15: ='Pastel Snicker''s'!F14 -> 201.96184 | F15: ='Pastel Snicker''s'!G14 -> 281.62809 | G15: ='Pastel Snicker''s'!H14 -> 392.15336 | H15: ='Pastel Snicker''s'!C14 -> 30.969949 | J15: =C15/$J$2 -> 0 | K15: =D15/$J$2 -> 73.624534 | L15: =E15/$J$2 -> 448.8041 | M15: =F15/$J$2 -> 625.84019 | N15: =G15/$J$2 -> 871.45192 | O15: =H15/$J$2 -> 68.822108 | Q15: =J15*(1-$Q$2) -> 0 | R15: =K15*(1-$Q$2) -> 69.943308 | S15: =L15*(1-$Q$2) -> 426.36389 | T15: =M15*(1-$Q$2) -> 594.54818 | U15: =N15*(1-$Q$2) -> 827.87932 | V15: =O15*(1-$Q$2) -> 65.381003
B16: Dulce de Leche | C16: 0 | D16: ='Pastel Vainilla'!E12 -> 0 | E16: ='Pastel Vainilla'!F12 -> 146.8559 | F16: ='Pastel Vainilla'!G12 -> 205.71168 | G16: ='Pastel Vainilla'!H12 -> 330.05251 | H16: ='Pastel Vainilla'!C12 -> 17.49273 | J16: =C16/$J$2 -> 0 | K16: =D16/$J$2 -> 0 | L16: =E16/$J$2 -> 326.34644 | M16: =F16/$J$2 -> 457.13706 | N16: =G16/$J$2 -> 733.45002 | O16: =H16/$J$2 -> 38.872733 | Q16: =J16*(1-$Q$2) -> 0 | R16: =K16*(1-$Q$2) -> 0 | S16: =L16*(1-$Q$2) -> 310.02912 | T16: =M16*(1-$Q$2) -> 434.2802 | U16: =N16*(1-$Q$2) -> 696.77752 | V16: =O16*(1-$Q$2) -> 36.929097
B17: 3 Leches | C17: 0 | D17: 0 | E17: 0 | F17: ='Pastel 3 Leches'!D13 -> 176.71615 | G17: ='Pastel 3 Leches'!E13 -> 401.53172 | H17: ='Pastel 3 Leches'!C13 -> 32.259831 | J17: =C17/$J$2 -> 0 | K17: =D17/$J$2 -> 0 | L17: =E17/$J$2 -> 0 | M17: =F17/$J$2 -> 392.70255 | N17: =G17/$J$2 -> 892.29271 | O17: =H17/$J$2 -> 71.688514 | Q17: =J17*(1-$Q$2) -> 0 | R17: =K17*(1-$Q$2) -> 0 | S17: =L17*(1-$Q$2) -> 0 | T17: =M17*(1-$Q$2) -> 373.06742 | U17: =N17*(1-$Q$2) -> 847.67808 | V17: =O17*(1-$Q$2) -> 68.104089
B18: 3 Leches Lotus | C18: ='Pastel 3 Leches Lotus'!F14 -> 41.38822 | F18: ='Pastel 3 Leches Lotus'!D14 -> 188.12781 | G18: ='Pastel 3 Leches Lotus'!E14 -> 504.65497 | H18: ='Pastel 3 Leches Lotus'!C14 -> 34.161774 | J18: =C18/$J$2 -> 91.973822 | K18: =D18/$J$2 -> 0 | L18: =E18/$J$2 -> 0 | M18: =F18/$J$2 -> 418.06179 | N18: =G18/$J$2 -> 1121.4555 | O18: =H18/$J$2 -> 75.915054 | Q18: =J18*(1-$Q$2) -> 87.375131 | R18: =K18*(1-$Q$2) -> 0 | S18: =L18*(1-$Q$2) -> 0 | T18: =M18*(1-$Q$2) -> 397.1587 | U18: =N18*(1-$Q$2) -> 1065.3827 | V18: =O18*(1-$Q$2) -> 72.119301
B19: Flan | C19: =Flan!D9 -> 22.94585 | D19: 0 | E19: 0 | F19: =Flan!G9 -> 241.70639 | G19: 0 | H19: =Flan!I9 -> 0 | J19: =C19/$J$2 -> 50.990777 | K19: =D19/$J$2 -> 0 | L19: =E19/$J$2 -> 0 | M19: =F19/$J$2 -> 537.1253 | N19: =G19/$J$2 -> 0 | O19: =H19/$J$2 -> 0 | Q19: =J19*(1-$Q$2) -> 48.441238 | R19: =K19*(1-$Q$2) -> 0 | S19: =L19*(1-$Q$2) -> 0 | T19: =M19*(1-$Q$2) -> 510.26904 | U19: =N19*(1-$Q$2) -> 0 | V19: =O19*(1-$Q$2) -> 0
A20: Vasos | B20: Fresas con crema | D20: =Vasos!D24 -> 17.018195 | G20: =Vasos!C24 -> 32.405495 | J20: =C20/$J$2 -> 0 | K20: =D20/$J$2 -> 37.818211 | L20: =E20/$J$2 -> 0 | M20: =F20/$J$2 -> 0 | N20: =G20/$J$2 -> 72.012211 | O20: =H20/$J$2 -> 0 | Q20: =J20*(1-$Q$2) -> 0 | R20: =K20*(1-$Q$2) -> 35.9273 | S20: =L20*(1-$Q$2) -> 0 | T20: =M20*(1-$Q$2) -> 0 | U20: =N20*(1-$Q$2) -> 68.411601 | V20: =O20*(1-$Q$2) -> 0
B21: Fresas con pay | D21: =Vasos!D25 -> 29.233566 | G21: =Vasos!C25 -> 44.620867 | J21: =C21/$J$2 -> 0 | K21: =D21/$J$2 -> 64.963481 | L21: =E21/$J$2 -> 0 | M21: =F21/$J$2 -> 0 | N21: =G21/$J$2 -> 99.157481 | O21: =H21/$J$2 -> 0 | Q21: =J21*(1-$Q$2) -> 0 | R21: =K21*(1-$Q$2) -> 61.715307 | S21: =L21*(1-$Q$2) -> 0 | T21: =M21*(1-$Q$2) -> 0 | U21: =N21*(1-$Q$2) -> 94.199607 | V21: =O21*(1-$Q$2) -> 0
B22: Crema | D22: =Vasos!D26 -> 9.8099053 | G22: =Vasos!C26 -> 17.08788 | J22: =C22/$J$2 -> 0 | K22: =D22/$J$2 -> 21.79979 | L22: =E22/$J$2 -> 0 | M22: =F22/$J$2 -> 0 | N22: =G22/$J$2 -> 37.973066 | O22: =H22/$J$2 -> 0 | Q22: =J22*(1-$Q$2) -> 0 | R22: =K22*(1-$Q$2) -> 20.7098 | S22: =L22*(1-$Q$2) -> 0 | T22: =M22*(1-$Q$2) -> 0 | U22: =N22*(1-$Q$2) -> 36.074413 | V22: =O22*(1-$Q$2) -> 0
A23: Bollos | B23: Chocolate | C23: =Bollos!D14 -> 14.435269 | D23: ='Pastel Fresas Con Crema'!E24 -> 0 | E23: ='Pastel Fresas Con Crema'!F24 -> 0 | F23: ='Pastel Fresas Con Crema'!G24 -> 0 | G23: ='Pastel Fresas Con Crema'!H24 -> 0 | H23: ='Pastel Fresas Con Crema'!C24 -> 0 | J23: =C23/$J$2 -> 32.078376 | K23: =D23/$J$2 -> 0 | L23: =E23/$J$2 -> 0 | M23: =F23/$J$2 -> 0 | N23: =G23/$J$2 -> 0 | O23: =H23/$J$2 -> 0 | Q23: =J23*(1-$Q$2) -> 30.474457 | R23: =K23*(1-$Q$2) -> 0 | S23: =L23*(1-$Q$2) -> 0 | T23: =M23*(1-$Q$2) -> 0 | U23: =N23*(1-$Q$2) -> 0 | V23: =O23*(1-$Q$2) -> 0
B24: Vainilla | C24: =Bollos!C14 -> 12.485675 | J24: =C24/$J$2 -> 27.745944 | K24: =D24/$J$2 -> 0 | L24: =E24/$J$2 -> 0 | M24: =F24/$J$2 -> 0 | N24: =G24/$J$2 -> 0 | O24: =H24/$J$2 -> 0 | Q24: =J24*(1-$Q$2) -> 26.358647 | R24: =K24*(1-$Q$2) -> 0 | S24: =L24*(1-$Q$2) -> 0 | T24: =M24*(1-$Q$2) -> 0 | U24: =N24*(1-$Q$2) -> 0 | V24: =O24*(1-$Q$2) -> 0
B25: Zanahoria | C25: =Bollos!F14 -> 12.928453 | D25: 0 | E25: ='Pastel Zanahoria'!F21 -> 0 | F25: ='Pastel Zanahoria'!G21 -> 0 | G25: ='Pastel Zanahoria'!H21 -> 0 | H25: ='Pastel Zanahoria'!C21 -> 0 | J25: =C25/$J$2 -> 28.729896 | K25: =D25/$J$2 -> 0 | L25: =E25/$J$2 -> 0 | M25: =F25/$J$2 -> 0 | N25: =G25/$J$2 -> 0 | O25: =H25/$J$2 -> 0 | Q25: =J25*(1-$Q$2) -> 27.293401 | R25: =K25*(1-$Q$2) -> 0 | S25: =L25*(1-$Q$2) -> 0 | T25: =M25*(1-$Q$2) -> 0 | U25: =N25*(1-$Q$2) -> 0 | V25: =O25*(1-$Q$2) -> 0
B26: Red Velvet | C26: =Bollos!E14 -> 13.970433 | D26: ='Pastel Chocolate'!E24 -> 0 | E26: ='Pastel Chocolate'!F24 -> 0 | F26: ='Pastel Chocolate'!G24 -> 0 | G26: ='Pastel Chocolate'!H24 -> 0 | H26: ='Pastel Chocolate'!C24 -> 0 | J26: =C26/$J$2 -> 31.045406 | K26: =D26/$J$2 -> 0 | L26: =E26/$J$2 -> 0 | M26: =F26/$J$2 -> 0 | N26: =G26/$J$2 -> 0 | O26: =H26/$J$2 -> 0 | Q26: =J26*(1-$Q$2) -> 29.493136 | R26: =K26*(1-$Q$2) -> 0 | S26: =L26*(1-$Q$2) -> 0 | T26: =M26*(1-$Q$2) -> 0 | U26: =N26*(1-$Q$2) -> 0 | V26: =O26*(1-$Q$2) -> 0
B27: Lotus | C27: =Bollos!G14 -> 20.155525 | D27: 0 | E27: 0 | F27: 0 | G27: 0 | H27: 0 | J27: =C27/$J$2 -> 44.790056 | K27: =D27/$J$2 -> 0 | L27: =E27/$J$2 -> 0 | M27: =F27/$J$2 -> 0 | N27: =G27/$J$2 -> 0 | O27: =H27/$J$2 -> 0 | Q27: =J27*(1-$Q$2) -> 42.550553 | R27: =K27*(1-$Q$2) -> 0 | S27: =L27*(1-$Q$2) -> 0 | T27: =M27*(1-$Q$2) -> 0 | U27: =N27*(1-$Q$2) -> 0 | V27: =O27*(1-$Q$2) -> 0
A28: Cheesecake | B28: Lotus | C28: =Cheesecake!J29 -> 60.99483 | D28: 0 | E28: =Cheesecake!G29 -> 205.30523 | F28: =Cheesecake!D29 -> 319.64719 | G28: 0 | H28: ='Pastel Fresas Con Crema'!C29 -> 0 | J28: =C28/$J$2 -> 135.54407 | K28: =D28/$J$2 -> 0 | L28: =E28/$J$2 -> 456.23384 | M28: =F28/$J$2 -> 710.32709 | N28: =G28/$J$2 -> 0 | O28: =H28/$J$2 -> 0 | Q28: =J28*(1-$Q$2) -> 128.76686 | R28: =K28*(1-$Q$2) -> 0 | S28: =L28*(1-$Q$2) -> 433.42214 | T28: =M28*(1-$Q$2) -> 674.81073 | U28: =N28*(1-$Q$2) -> 0 | V28: =O28*(1-$Q$2) -> 0
B29: Tortuga | C29: =Cheesecake!U29 -> 52.683417 | D29: ='Pastel 3 Pecados'!E31 -> 0 | E29: =Cheesecake!R29 -> 182.33088 | F29: =Cheesecake!O29 -> 254.16219 | G29: ='Pastel 3 Pecados'!H31 -> 0 | H29: ='Pastel 3 Pecados'!C31 -> 0 | J29: =C29/$J$2 -> 117.07426 | K29: =D29/$J$2 -> 0 | L29: =E29/$J$2 -> 405.17974 | M29: =F29/$J$2 -> 564.80487 | N29: =G29/$J$2 -> 0 | O29: =H29/$J$2 -> 0 | Q29: =J29*(1-$Q$2) -> 111.22055 | R29: =K29*(1-$Q$2) -> 0 | S29: =L29*(1-$Q$2) -> 384.92075 | T29: =M29*(1-$Q$2) -> 536.56463 | U29: =N29*(1-$Q$2) -> 0 | V29: =O29*(1-$Q$2) -> 0
B30: Brownie | C30: =Cheesecake!AF29 -> 45.518018 | D30: 0 | E30: =Cheesecake!AC29 -> 179.67515 | F30: =Cheesecake!Z29 -> 250.2993 | G30: 0 | H30: 0 | J30: =C30/$J$2 -> 101.15115 | K30: =D30/$J$2 -> 0 | L30: =E30/$J$2 -> 399.2781 | M30: =F30/$J$2 -> 556.22067 | N30: =G30/$J$2 -> 0 | O30: =H30/$J$2 -> 0 | Q30: =J30*(1-$Q$2) -> 96.093595 | R30: =K30*(1-$Q$2) -> 0 | S30: =L30*(1-$Q$2) -> 379.3142 | T30: =M30*(1-$Q$2) -> 528.40964 | U30: =N30*(1-$Q$2) -> 0 | V30: =O30*(1-$Q$2) -> 0
B31: Zarzamora | C31: =Cheesecake!AQ29 -> 52.866543 | D31: 0 | E31: =Cheesecake!AN29 -> 198.97726 | F31: =Cheesecake!AK29 -> 286.3147 | G31: 0 | H31: 0 | J31: =C31/$J$2 -> 117.48121 | K31: =D31/$J$2 -> 0 | L31: =E31/$J$2 -> 442.1717 | M31: =F31/$J$2 -> 636.25488 | N31: =G31/$J$2 -> 0 | O31: =H31/$J$2 -> 0 | Q31: =J31*(1-$Q$2) -> 111.60715 | R31: =K31*(1-$Q$2) -> 0 | S31: =L31*(1-$Q$2) -> 420.06311 | T31: =M31*(1-$Q$2) -> 604.44214 | U31: =N31*(1-$Q$2) -> 0 | V31: =O31*(1-$Q$2) -> 0
B32: Zanahoria | C32: 0 | D32: 0 | E32: 0 | F32: 0 | G32: 0 | H32: 0 | J32: =C32/$J$2 -> 0 | K32: =D32/$J$2 -> 0 | L32: =E32/$J$2 -> 0 | M32: =F32/$J$2 -> 0 | N32: =G32/$J$2 -> 0 | O32: =H32/$J$2 -> 0 | Q32: =J32*(1-$Q$2) -> 0 | R32: =K32*(1-$Q$2) -> 0 | S32: =L32*(1-$Q$2) -> 0 | T32: =M32*(1-$Q$2) -> 0 | U32: =N32*(1-$Q$2) -> 0 | V32: =O32*(1-$Q$2) -> 0
B33: Cinnamon | C33: 0 | D33: 0 | E33: 0 | F33: 0 | G33: 0 | H33: 0 | J33: =C33/$J$2 -> 0 | K33: =D33/$J$2 -> 0 | L33: =E33/$J$2 -> 0 | M33: =F33/$J$2 -> 0 | N33: =G33/$J$2 -> 0 | O33: =H33/$J$2 -> 0 | Q33: =J33*(1-$Q$2) -> 0 | R33: =K33*(1-$Q$2) -> 0 | S33: =L33*(1-$Q$2) -> 0 | T33: =M33*(1-$Q$2) -> 0 | U33: =N33*(1-$Q$2) -> 0 | V33: =O33*(1-$Q$2) -> 0
B34: Manzana | C34: 0 | D34: 0 | E34: 0 | F34: 0 | G34: 0 | H34: 0 | J34: =C34/$J$2 -> 0 | K34: =D34/$J$2 -> 0 | L34: =E34/$J$2 -> 0 | M34: =F34/$J$2 -> 0 | N34: =G34/$J$2 -> 0 | O34: =H34/$J$2 -> 0 | Q34: =J34*(1-$Q$2) -> 0 | R34: =K34*(1-$Q$2) -> 0 | S34: =L34*(1-$Q$2) -> 0 | T34: =M34*(1-$Q$2) -> 0 | U34: =N34*(1-$Q$2) -> 0 | V34: =O34*(1-$Q$2) -> 0
B35: Limón | C35: =Cheesecake!BB29 -> 51.531339 | D35: 0 | E35: =Cheesecake!AY29 -> 168.3096 | F35: =Cheesecake!AV29 -> 244.24056 | G35: 0 | H35: 0 | J35: =C35/$J$2 -> 114.51409 | K35: =D35/$J$2 -> 0 | L35: =E35/$J$2 -> 374.02133 | M35: =F35/$J$2 -> 542.7568 | N35: =G35/$J$2 -> 0 | O35: =H35/$J$2 -> 0 | Q35: =J35*(1-$Q$2) -> 108.78838 | R35: =K35*(1-$Q$2) -> 0 | S35: =L35*(1-$Q$2) -> 355.32027 | T35: =M35*(1-$Q$2) -> 515.61896 | U35: =N35*(1-$Q$2) -> 0 | V35: =O35*(1-$Q$2) -> 0
B36: Rol Canela | C36: =Cheesecake!BM29 -> 56.522501 | D36: 0 | E36: =Cheesecake!BJ29 -> 194.38114 | F36: =Cheesecake!BG29 -> 280.56721 | G36: 0 | H36: 0 | J36: =C36/$J$2 -> 125.60556 | K36: =D36/$J$2 -> 0 | L36: =E36/$J$2 -> 431.95809 | M36: =F36/$J$2 -> 623.4827 | N36: =G36/$J$2 -> 0 | O36: =H36/$J$2 -> 0 | Q36: =J36*(1-$Q$2) -> 119.32528 | R36: =K36*(1-$Q$2) -> 0 | S36: =L36*(1-$Q$2) -> 410.36019 | T36: =M36*(1-$Q$2) -> 592.30856 | U36: =N36*(1-$Q$2) -> 0 | V36: =O36*(1-$Q$2) -> 0
B37: Manzana | C37: =Cheesecake!BX29 -> 47.115889 | D37: 0 | E37: =Cheesecake!BU29 -> 159.56781 | F37: =Cheesecake!BR29 -> 260.52072 | G37: 0 | H37: 0 | J37: =C37/$J$2 -> 104.70198 | K37: =D37/$J$2 -> 0 | L37: =E37/$J$2 -> 354.59513 | M37: =F37/$J$2 -> 578.93494 | N37: =G37/$J$2 -> 0 | O37: =H37/$J$2 -> 0 | Q37: =J37*(1-$Q$2) -> 99.466877 | R37: =K37*(1-$Q$2) -> 0 | S37: =L37*(1-$Q$2) -> 336.86537 | T37: =M37*(1-$Q$2) -> 549.9882 | U37: =N37*(1-$Q$2) -> 0 | V37: =O37*(1-$Q$2) -> 0
C39: Individual | D39: Mini | E39: Chico | F39: Mediano | G39: Grande | H39: Rebanada | J39: Individual | K39: Mini | L39: Chico | M39: Mediano | N39: Grande | O39: Rebanada | Q39: Individual | R39: Mini | S39: Chico | T39: Mediano | U39: Grande | V39: Rebanada
A40: Promedio | B40: Pastel | C40: 0 | D40: =AVERAGE(D10,D11,D13,D14) -> 70.518725 | E40: =AVERAGE(E10:E12,E14:E15) -> 166.65862 | F40: =AVERAGE(F10:F12,F14:F17) -> 222.6556 | G40: =AVERAGE(G10:G12,G14:G17) -> 352.71232 | H40: =AVERAGE(H10:H12,H14:H17) -> 25.914914 | J40: =C40/$J$2 -> 0 | K40: =D40/$J$2 -> 156.70828 | L40: =E40/$J$2 -> 370.35249 | M40: =F40/$J$2 -> 494.79022 | N40: =G40/$J$2 -> 783.80516 | O40: =H40/$J$2 -> 57.588698 | Q40: =J40*(1-$Q$2) -> 0 | R40: =K40*(1-$Q$2) -> 148.87286 | S40: =L40*(1-$Q$2) -> 351.83487 | T40: =M40*(1-$Q$2) -> 470.05071 | U40: =N40*(1-$Q$2) -> 744.6149 | V40: =O40*(1-$Q$2) -> 54.709263
B41: Pay | C41: =AVERAGE(C4:C7) -> 19.176338 | D41: =AVERAGE(D4:D9) -> 0 | E41: =AVERAGE(E4:E9) -> 0 | F41: =AVERAGE(F4:F6) -> 141.39691 | G41: =AVERAGE(G4:G6) -> 236.54777 | H41: =AVERAGE(H4:H6) -> 32.269112 | J41: =C41/$J$2 -> 42.614084 | K41: =D41/$J$2 -> 0 | L41: =E41/$J$2 -> 0 | M41: =F41/$J$2 -> 314.21537 | N41: =G41/$J$2 -> 525.66172 | O41: =H41/$J$2 -> 71.709137 | Q41: =J41*(1-$Q$2) -> 40.48338 | R41: =K41*(1-$Q$2) -> 0 | S41: =L41*(1-$Q$2) -> 0 | T41: =M41*(1-$Q$2) -> 298.5046 | U41: =N41*(1-$Q$2) -> 499.37864 | V41: =O41*(1-$Q$2) -> 68.123681
...

Sheet Lista de Costo Produccion
I1: Precio Ajustado | J1: 0.45 | O1: Mínimo de margen | P1: 0.4 | U1: Buen margen | V1: 0.35 | AA1: Mejor margen | AB1: 0.3 | AG1: Precio Propuesto | AM1: Precio Ajustado | AN1: 0.45
C2: Individual | D2: Mini | E2: Chico | F2: Mediano | G2: Grande | H2: Rebanada | I2: Individual | J2: Mini | K2: Chico | L2: Mediano | M2: Grande | N2: Rebanada | O2: Individual | P2: Mini | Q2: Chico | R2: Mediano | S2: Grande | T2: Rebanada | U2: Individual | V2: Mini | W2: Chico | X2: Mediano | Y2: Grande | Z2: Rebanada | AA2: Individual | AB2: Mini | AC2: Chico | AD2: Mediano | AE2: Grande | AF2: Rebanada | AG2: Individual | AH2: Mini | AI2: Chico | AJ2: Mediano | AK2: Grande | AL2: Rebanada | AM2: Individual | AN2: Mini | AO2: Chico | AP2: Mediano | AQ2: Grande | AR2: Rebanada
A3: Pay | B3: Fresa | C3: =Pay!C53 -> 18.916121 | D3: 0 | E3: 0 | F3: =Pay!D53 -> 140.58423 | G3: =Pay!E53 -> 240.03393 | H3: =Pay!F53 -> 32.704881 | I3: =_xlfn.IFNA(C3/$J$1,0) -> 42.035824 | J3: =_xlfn.IFNA(D3/$J$1,0) -> 0 | K3: =_xlfn.IFNA(E3/$J$1,0) -> 0 | L3: =_xlfn.IFNA(F3/$J$1,0) -> 312.4094 | M3: =_xlfn.IFNA(G3/$J$1,0) -> 533.40873 | N3: =_xlfn.IFNA(H3/$J$1,0) -> 72.677513 | O3: =_xlfn.IFNA(C3/$P$1,0) -> 47.290302 | P3: =_xlfn.IFNA(D3/$P$1,0) -> 0 | Q3: =_xlfn.IFNA(E3/$P$1,0) -> 0 | R3: =_xlfn.IFNA(F3/$P$1,0) -> 351.46057 | S3: =_xlfn.IFNA(G3/$P$1,0) -> 600.08482 | T3: =_xlfn.IFNA(H3/$P$1,0) -> 81.762202 | U3: =_xlfn.IFNA(C3/$V$1,0) -> 54.04606 | V3: =_xlfn.IFNA(D3/$V$1,0) -> 0 | W3: =_xlfn.IFNA(E3/$V$1,0) -> 0 | X3: =_xlfn.IFNA(F3/$V$1,0) -> 401.66922 | Y3: =_xlfn.IFNA(G3/$V$1,0) -> 685.81122 | Z3: =_xlfn.IFNA(H3/$V$1,0) -> 93.442517 | AA3: =_xlfn.IFNA(C3/$AB$1,0) -> 63.053737 | AB3: =_xlfn.IFNA(D3/$AB$1,0) -> 0 | AC3: =_xlfn.IFNA(E3/$AB$1,0) -> 0 | AD3: =_xlfn.IFNA(F3/$AB$1,0) -> 468.61409 | AE3: =_xlfn.IFNA(G3/$AB$1,0) -> 800.11309 | AF3: =_xlfn.IFNA(H3/$AB$1,0) -> 109.01627 | AG3: 55 | AJ3: 395 | AK3: 495 | AL3: 70 | AM3: =_xlfn.IFNA(C3/$AN$1,0) -> 42.035824 | AN3: =_xlfn.IFNA(D3/$AN$1,0) -> 0 | AO3: =_xlfn.IFNA(E3/$AN$1,0) -> 0 | AP3: =_xlfn.IFNA(F3/$AN$1,0) -> 312.4094 | AQ3: =_xlfn.IFNA(G3/$AN$1,0) -> 533.40873 | AR3: =_xlfn.IFNA(H3/$AN$1,0) -> 72.677513
B4: Guayaba | C4: =Pay!C54 -> 19.055935 | D4: 0 | E4: 0 | F4: =Pay!D54 -> 148.26907 | G4: =Pay!E54 -> 240.58042 | H4: =Pay!F54 -> 32.773193 | I4: =_xlfn.IFNA(C4/$J$1,0) -> 42.346523 | J4: =_xlfn.IFNA(D4/$J$1,0) -> 0 | K4: =_xlfn.IFNA(E4/$J$1,0) -> 0 | L4: =_xlfn.IFNA(F4/$J$1,0) -> 329.48683 | M4: =_xlfn.IFNA(G4/$J$1,0) -> 534.62316 | N4: =_xlfn.IFNA(H4/$J$1,0) -> 72.829317 | O4: =_xlfn.IFNA(C4/$P$1,0) -> 47.639839 | P4: =_xlfn.IFNA(D4/$P$1,0) -> 0 | Q4: =_xlfn.IFNA(E4/$P$1,0) -> 0 | R4: =_xlfn.IFNA(F4/$P$1,0) -> 370.67269 | S4: =_xlfn.IFNA(G4/$P$1,0) -> 601.45105 | T4: =_xlfn.IFNA(H4/$P$1,0) -> 81.932982 | U4: =_xlfn.IFNA(C4/$V$1,0) -> 54.44553 | V4: =_xlfn.IFNA(D4/$V$1,0) -> 0 | W4: =_xlfn.IFNA(E4/$V$1,0) -> 0 | X4: =_xlfn.IFNA(F4/$V$1,0) -> 423.62593 | Y4: =_xlfn.IFNA(G4/$V$1,0) -> 687.37263 | Z4: =_xlfn.IFNA(H4/$V$1,0) -> 93.637693 | AA4: =_xlfn.IFNA(C4/$AB$1,0) -> 63.519785 | AB4: =_xlfn.IFNA(D4/$AB$1,0) -> 0 | AC4: =_xlfn.IFNA(E4/$AB$1,0) -> 0 | AD4: =_xlfn.IFNA(F4/$AB$1,0) -> 494.23025 | AE4: =_xlfn.IFNA(G4/$AB$1,0) -> 801.93474 | AF4: =_xlfn.IFNA(H4/$AB$1,0) -> 109.24398 | AG4: 55 | AJ4: 380 | AK4: 475 | AL4: 70 | AM4: =_xlfn.IFNA(C4/$AN$1,0) -> 42.346523 | AN4: =_xlfn.IFNA(D4/$AN$1,0) -> 0 | AO4: =_xlfn.IFNA(E4/$AN$1,0) -> 0 | AP4: =_xlfn.IFNA(F4/$AN$1,0) -> 329.48683 | AQ4: =_xlfn.IFNA(G4/$AN$1,0) -> 534.62316 | AR4: =_xlfn.IFNA(H4/$AN$1,0) -> 72.829317
B5: Galleta con cajeta | C5: =Pay!C55 -> 20.11006 | D5: 0 | E5: 0 | F5: =Pay!D55 -> 135.33744 | G5: =Pay!E55 -> 229.02898 | H5: =Pay!F55 -> 31.329262 | I5: =_xlfn.IFNA(C5/$J$1,0) -> 44.689022 | J5: =_xlfn.IFNA(D5/$J$1,0) -> 0 | K5: =_xlfn.IFNA(E5/$J$1,0) -> 0 | L5: =_xlfn.IFNA(F5/$J$1,0) -> 300.74987 | M5: =_xlfn.IFNA(G5/$J$1,0) -> 508.95328 | N5: =_xlfn.IFNA(H5/$J$1,0) -> 69.620583 | O5: =_xlfn.IFNA(C5/$P$1,0) -> 50.27515 | P5: =_xlfn.IFNA(D5/$P$1,0) -> 0 | Q5: =_xlfn.IFNA(E5/$P$1,0) -> 0 | R5: =_xlfn.IFNA(F5/$P$1,0) -> 338.3436 | S5: =_xlfn.IFNA(G5/$P$1,0) -> 572.57244 | T5: =_xlfn.IFNA(H5/$P$1,0) -> 78.323155 | U5: =_xlfn.IFNA(C5/$V$1,0) -> 57.457314 | V5: =_xlfn.IFNA(D5/$V$1,0) -> 0 | W5: =_xlfn.IFNA(E5/$V$1,0) -> 0 | X5: =_xlfn.IFNA(F5/$V$1,0) -> 386.6784 | Y5: =_xlfn.IFNA(G5/$V$1,0) -> 654.36851 | Z5: =_xlfn.IFNA(H5/$V$1,0) -> 89.512178 | AA5: =_xlfn.IFNA(C5/$AB$1,0) -> 67.033534 | AB5: =_xlfn.IFNA(D5/$AB$1,0) -> 0 | AC5: =_xlfn.IFNA(E5/$AB$1,0) -> 0 | AD5: =_xlfn.IFNA(F5/$AB$1,0) -> 451.1248 | AE5: =_xlfn.IFNA(G5/$AB$1,0) -> 763.42992 | AF5: =_xlfn.IFNA(H5/$AB$1,0) -> 104.43087 | AG5: 55 | AJ5: 370 | AK5: 475 | AL5: 70 | AM5: =_xlfn.IFNA(C5/$AN$1,0) -> 44.689022 | AN5: =_xlfn.IFNA(D5/$AN$1,0) -> 0 | AO5: =_xlfn.IFNA(E5/$AN$1,0) -> 0 | AP5: =_xlfn.IFNA(F5/$AN$1,0) -> 300.74987 | AQ5: =_xlfn.IFNA(G5/$AN$1,0) -> 508.95328 | AR5: =_xlfn.IFNA(H5/$AN$1,0) -> 69.620583
B6: Oreo | C6: =Pay!C57 -> 18.623235 | D6: 0 | E6: 0 | F6: =Pay!D57 -> 139.81162 | G6: =Pay!E57 -> 238.53794 | H6: =Pay!F57 -> 32.517883 | I6: =_xlfn.IFNA(C6/$J$1,0) -> 41.384968 | J6: =_xlfn.IFNA(D6/$J$1,0) -> 0 | K6: =_xlfn.IFNA(E6/$J$1,0) -> 0 | L6: =_xlfn.IFNA(F6/$J$1,0) -> 310.69249 | M6: =_xlfn.IFNA(G6/$J$1,0) -> 530.08432 | N6: =_xlfn.IFNA(H6/$J$1,0) -> 72.261962 | O6: =_xlfn.IFNA(C6/$P$1,0) -> 46.558089 | P6: =_xlfn.IFNA(D6/$P$1,0) -> 0 | Q6: =_xlfn.IFNA(E6/$P$1,0) -> 0 | R6: =_xlfn.IFNA(F6/$P$1,0) -> 349.52905 | S6: =_xlfn.IFNA(G6/$P$1,0) -> 596.34486 | T6: =_xlfn.IFNA(H6/$P$1,0) -> 81.294708 | U6: =_xlfn.IFNA(C6/$V$1,0) -> 53.209244 | V6: =_xlfn.IFNA(D6/$V$1,0) -> 0 | W6: =_xlfn.IFNA(E6/$V$1,0) -> 0 | X6: =_xlfn.IFNA(F6/$V$1,0) -> 399.46178 | Y6: =_xlfn.IFNA(G6/$V$1,0) -> 681.53698 | Z6: =_xlfn.IFNA(H6/$V$1,0) -> 92.908237 | AA6: =_xlfn.IFNA(C6/$AB$1,0) -> 62.077452 | AB6: =_xlfn.IFNA(D6/$AB$1,0) -> 0 | AC6: =_xlfn.IFNA(E6/$AB$1,0) -> 0 | AD6: =_xlfn.IFNA(F6/$AB$1,0) -> 466.03874 | AE6: =_xlfn.IFNA(G6/$AB$1,0) -> 795.12648 | AF6: =_xlfn.IFNA(H6/$AB$1,0) -> 108.39294 | AG6: 55 | AJ6: 395 | AK6: 495 | AL6: 70 | AM6: =_xlfn.IFNA(C6/$AN$1,0) -> 41.384968 | AN6: =_xlfn.IFNA(D6/$AN$1,0) -> 0 | AO6: =_xlfn.IFNA(E6/$AN$1,0) -> 0 | AP6: =_xlfn.IFNA(F6/$AN$1,0) -> 310.69249 | AQ6: =_xlfn.IFNA(G6/$AN$1,0) -> 530.08432 | AR6: =_xlfn.IFNA(H6/$AN$1,0) -> 72.261962
B7: Plátano
B8: Pay horneado | C8: =Pay!C58 -> 0 | D8: 0 | E8: 0 | F8: =Pay!D58 -> 86.851881 | G8: =Pay!E58 -> 148.87704 | H8: =Pay!F58 -> 21.310271 | I8: =_xlfn.IFNA(C8/$J$1,0) -> 0 | J8: =_xlfn.IFNA(D8/$J$1,0) -> 0 | K8: =_xlfn.IFNA(E8/$J$1,0) -> 0 | L8: =_xlfn.IFNA(F8/$J$1,0) -> 193.00418 | M8: =_xlfn.IFNA(G8/$J$1,0) -> 330.83788 | N8: =_xlfn.IFNA(H8/$J$1,0) -> 47.356157 | O8: =_xlfn.IFNA(C8/$P$1,0) -> 0 | P8: =_xlfn.IFNA(D8/$P$1,0) -> 0 | Q8: =_xlfn.IFNA(E8/$P$1,0) -> 0 | R8: =_xlfn.IFNA(F8/$P$1,0) -> 217.1297 | S8: =_xlfn.IFNA(G8/$P$1,0) -> 372.19261 | T8: =_xlfn.IFNA(H8/$P$1,0) -> 53.275676 | U8: =_xlfn.IFNA(C8/$V$1,0) -> 0 | V8: =_xlfn.IFNA(D8/$V$1,0) -> 0 | W8: =_xlfn.IFNA(E8/$V$1,0) -> 0 | X8: =_xlfn.IFNA(F8/$V$1,0) -> 248.14823 | Y8: =_xlfn.IFNA(G8/$V$1,0) -> 425.36298 | Z8: =_xlfn.IFNA(H8/$V$1,0) -> 60.886487 | AA8: =_xlfn.IFNA(C8/$AB$1,0) -> 0 | AB8: =_xlfn.IFNA(D8/$AB$1,0) -> 0 | AC8: =_xlfn.IFNA(E8/$AB$1,0) -> 0 | AD8: =_xlfn.IFNA(F8/$AB$1,0) -> 289.50627 | AE8: =_xlfn.IFNA(G8/$AB$1,0) -> 496.25681 | AF8: =_xlfn.IFNA(H8/$AB$1,0) -> 71.034235 | AG8: 45 | AL8: 60 | AM8: =_xlfn.IFNA(C8/$AN$1,0) -> 0 | AN8: =_xlfn.IFNA(D8/$AN$1,0) -> 0 | AO8: =_xlfn.IFNA(E8/$AN$1,0) -> 0 | AP8: =_xlfn.IFNA(F8/$AN$1,0) -> 193.00418 | AQ8: =_xlfn.IFNA(G8/$AN$1,0) -> 330.83788 | AR8: =_xlfn.IFNA(H8/$AN$1,0) -> 47.356157
B9: Pay de queso | C9: =Pay!C59 -> 0 | D9: 0 | E9: 0 | F9: =Pay!D59 -> 115.18762 | G9: =Pay!E59 -> 195.44594 | H9: =Pay!F59 -> 27.131383 | I9: =_xlfn.IFNA(C9/$J$1,0) -> 0 | J9: =_xlfn.IFNA(D9/$J$1,0) -> 0 | K9: =_xlfn.IFNA(E9/$J$1,0) -> 0 | L9: =_xlfn.IFNA(F9/$J$1,0) -> 255.97249 | M9: =_xlfn.IFNA(G9/$J$1,0) -> 434.32432 | N9: =_xlfn.IFNA(H9/$J$1,0) -> 60.291962 | O9: =_xlfn.IFNA(C9/$P$1,0) -> 0 | P9: =_xlfn.IFNA(D9/$P$1,0) -> 0 | Q9: =_xlfn.IFNA(E9/$P$1,0) -> 0 | R9: =_xlfn.IFNA(F9/$P$1,0) -> 287.96905 | S9: =_xlfn.IFNA(G9/$P$1,0) -> 488.61486 | T9: =_xlfn.IFNA(H9/$P$1,0) -> 67.828458 | U9: =_xlfn.IFNA(C9/$V$1,0) -> 0 | V9: =_xlfn.IFNA(D9/$V$1,0) -> 0 | W9: =_xlfn.IFNA(E9/$V$1,0) -> 0 | X9: =_xlfn.IFNA(F9/$V$1,0) -> 329.10749 | Y9: =_xlfn.IFNA(G9/$V$1,0) -> 558.41698 | Z9: =_xlfn.IFNA(H9/$V$1,0) -> 77.518237 | AA9: =_xlfn.IFNA(C9/$AB$1,0) -> 0 | AB9: =_xlfn.IFNA(D9/$AB$1,0) -> 0 | AC9: =_xlfn.IFNA(E9/$AB$1,0) -> 0 | AD9: =_xlfn.IFNA(F9/$AB$1,0) -> 383.95874 | AE9: =_xlfn.IFNA(G9/$AB$1,0) -> 651.48648 | AF9: =_xlfn.IFNA(H9/$AB$1,0) -> 90.437944 | AG9: 50 | AL9: 65 | AM9: =_xlfn.IFNA(C9/$AN$1,0) -> 0 | AN9: =_xlfn.IFNA(D9/$AN$1,0) -> 0 | AO9: =_xlfn.IFNA(E9/$AN$1,0) -> 0 | AP9: =_xlfn.IFNA(F9/$AN$1,0) -> 255.97249 | AQ9: =_xlfn.IFNA(G9/$AN$1,0) -> 434.32432 | AR9: =_xlfn.IFNA(H9/$AN$1,0) -> 60.291962
A10: Pastel | B10: Fresas con Crema | C10: ='Pastel Fresas Con Crema'!D12 -> 0 | D10: ='Pastel Fresas Con Crema'!E13 -> 70.789681 | E10: ='Pastel Fresas Con Crema'!F13 -> 139.62928 | F10: ='Pastel Fresas Con Crema'!G13 -> 197.69975 | G10: ='Pastel Fresas Con Crema'!H13 -> 323.02917 | H10: ='Pastel Fresas Con Crema'!C13 -> 22.577115 | I10: =_xlfn.IFNA(C10/$J$1,0) -> 0 | J10: =_xlfn.IFNA(D10/$J$1,0) -> 157.3104 | K10: =_xlfn.IFNA(E10/$J$1,0) -> 310.28729 | L10: =_xlfn.IFNA(F10/$J$1,0) -> 439.33279 | M10: =_xlfn.IFNA(G10/$J$1,0) -> 717.8426 | N10: =_xlfn.IFNA(H10/$J$1,0) -> 50.171367 | O10: =_xlfn.IFNA(C10/$P$1,0) -> 0 | P10: =_xlfn.IFNA(D10/$P$1,0) -> 176.9742 | Q10: =_xlfn.IFNA(E10/$P$1,0) -> 349.07321 | R10: =_xlfn.IFNA(F10/$P$1,0) -> 494.24938 | S10: =_xlfn.IFNA(G10/$P$1,0) -> 807.57292 | T10: =_xlfn.IFNA(H10/$P$1,0) -> 56.442788 | U10: =_xlfn.IFNA(C10/$V$1,0) -> 0 | V10: =_xlfn.IFNA(D10/$V$1,0) -> 202.25623 | W10: =_xlfn.IFNA(E10/$V$1,0) -> 398.94081 | X10: =_xlfn.IFNA(F10/$V$1,0) -> 564.85644 | Y10: =_xlfn.IFNA(G10/$V$1,0) -> 922.94048 | Z10: =_xlfn.IFNA(H10/$V$1,0) -> 64.506044 | AA10: =_xlfn.IFNA(C10/$AB$1,0) -> 0 | AB10: =_xlfn.IFNA(D10/$AB$1,0) -> 235.9656 | AC10: =_xlfn.IFNA(E10/$AB$1,0) -> 465.43094 | AD10: =_xlfn.IFNA(F10/$AB$1,0) -> 658.99918 | AE10: =_xlfn.IFNA(G10/$AB$1,0) -> 1076.7639 | AF10: =_xlfn.IFNA(H10/$AB$1,0) -> 75.257051 | AH10: 185 | AI10: 335 | AJ10: 490 | AK10: 700 | AL10: 70 | AM10: =_xlfn.IFNA(C10/$AN$1,0) -> 0 | AN10: =_xlfn.IFNA(D10/$AN$1,0) -> 157.3104 | AO10: =_xlfn.IFNA(E10/$AN$1,0) -> 310.28729 | AP10: =_xlfn.IFNA(F10/$AN$1,0) -> 439.33279 | AQ10: =_xlfn.IFNA(G10/$AN$1,0) -> 717.8426 | AR10: =_xlfn.IFNA(H10/$AN$1,0) -> 50.171367
B11: 3 Pecados | C11: 0 | D11: ='Pastel 3 Pecados'!E18 -> 64.125646 | E11: ='Pastel 3 Pecados'!F18 -> 163.26597 | F11: ='Pastel 3 Pecados'!G18 -> 234.88562 | G11: ='Pastel 3 Pecados'!H18 -> 350.57494 | H11: ='Pastel 3 Pecados'!C18 -> 26.295702 | I11: =_xlfn.IFNA(C11/$J$1,0) -> 0 | J11: =_xlfn.IFNA(D11/$J$1,0) -> 142.50144 | K11: =_xlfn.IFNA(E11/$J$1,0) -> 362.81327 | L11: =_xlfn.IFNA(F11/$J$1,0) -> 521.96804 | M11: =_xlfn.IFNA(G11/$J$1,0) -> 779.05543 | N11: =_xlfn.IFNA(H11/$J$1,0) -> 58.434893 | O11: =_xlfn.IFNA(C11/$P$1,0) -> 0 | P11: =_xlfn.IFNA(D11/$P$1,0) -> 160.31412 | Q11: =_xlfn.IFNA(E11/$P$1,0) -> 408.16493 | R11: =_xlfn.IFNA(F11/$P$1,0) -> 587.21405 | S11: =_xlfn.IFNA(G11/$P$1,0) -> 876.43736 | T11: =_xlfn.IFNA(H11/$P$1,0) -> 65.739255 | U11: =_xlfn.IFNA(C11/$V$1,0) -> 0 | V11: =_xlfn.IFNA(D11/$V$1,0) -> 183.21613 | W11: =_xlfn.IFNA(E11/$V$1,0) -> 466.4742 | X11: =_xlfn.IFNA(F11/$V$1,0) -> 671.10177 | Y11: =_xlfn.IFNA(G11/$V$1,0) -> 1001.6427 | Z11: =_xlfn.IFNA(H11/$V$1,0) -> 75.130577 | AA11: =_xlfn.IFNA(C11/$AB$1,0) -> 0 | AB11: =_xlfn.IFNA(D11/$AB$1,0) -> 213.75215 | AC11: =_xlfn.IFNA(E11/$AB$1,0) -> 544.2199 | AD11: =_xlfn.IFNA(F11/$AB$1,0) -> 782.95207 | AE11: =_xlfn.IFNA(G11/$AB$1,0) -> 1168.5831 | AF11: =_xlfn.IFNA(H11/$AB$1,0) -> 87.65234 | AH11: 185 | AI11: 340 | AJ11: 490 | AK11: 700 | AL11: 70 | AM11: =_xlfn.IFNA(C11/$AN$1,0) -> 0 | AN11: =_xlfn.IFNA(D11/$AN$1,0) -> 142.50144 | AO11: =_xlfn.IFNA(E11/$AN$1,0) -> 362.81327 | AP11: =_xlfn.IFNA(F11/$AN$1,0) -> 521.96804 | AQ11: =_xlfn.IFNA(G11/$AN$1,0) -> 779.05543 | AR11: =_xlfn.IFNA(H11/$AN$1,0) -> 58.434893
B12: Zanahoria | C12: 0 | D12: 0 | E12: ='Pastel Zanahoria'!F12 -> 151.95679 | F12: ='Pastel Zanahoria'!G12 -> 207.49008 | G12: ='Pastel Zanahoria'!H12 -> 317.43002 | H12: ='Pastel Zanahoria'!C12 -> 23.556148 | I12: =_xlfn.IFNA(C12/$J$1,0) -> 0 | J12: =_xlfn.IFNA(D12/$J$1,0) -> 0 | K12: =_xlfn.IFNA(E12/$J$1,0) -> 337.68175 | L12: =_xlfn.IFNA(F12/$J$1,0) -> 461.08908 | M12: =_xlfn.IFNA(G12/$J$1,0) -> 705.40005 | N12: =_xlfn.IFNA(H12/$J$1,0) -> 52.346997 | O12: =_xlfn.IFNA(C12/$P$1,0) -> 0 | P12: =_xlfn.IFNA(D12/$P$1,0) -> 0 | Q12: =_xlfn.IFNA(E12/$P$1,0) -> 379.89196 | R12: =_xlfn.IFNA(F12/$P$1,0) -> 518.72521 | S12: =_xlfn.IFNA(G12/$P$1,0) -> 793.57506 | T12: =_xlfn.IFNA(H12/$P$1,0) -> 58.890371 | U12: =_xlfn.IFNA(C12/$V$1,0) -> 0 | V12: =_xlfn.IFNA(D12/$V$1,0) -> 0 | W12: =_xlfn.IFNA(E12/$V$1,0) -> 434.16225 | X12: =_xlfn.IFNA(F12/$V$1,0) -> 592.82881 | Y12: =_xlfn.IFNA(G12/$V$1,0) -> 906.94293 | Z12: =_xlfn.IFNA(H12/$V$1,0) -> 67.303281 | AA12: =_xlfn.IFNA(C12/$AB$1,0) -> 0 | AB12: =_xlfn.IFNA(D12/$AB$1,0) -> 0 | AC12: =_xlfn.IFNA(E12/$AB$1,0) -> 506.52262 | AD12: =_xlfn.IFNA(F12/$AB$1,0) -> 691.63362 | AE12: =_xlfn.IFNA(G12/$AB$1,0) -> 1058.1001 | AF12: =_xlfn.IFNA(H12/$AB$1,0) -> 78.520495 | AI12: 330 | AJ12: 440 | AK12: 700 | AL12: 70 | AM12: =_xlfn.IFNA(C12/$AN$1,0) -> 0 | AN12: =_xlfn.IFNA(D12/$AN$1,0) -> 0 | AO12: =_xlfn.IFNA(E12/$AN$1,0) -> 337.68175 | AP12: =_xlfn.IFNA(F12/$AN$1,0) -> 461.08908 | AQ12: =_xlfn.IFNA(G12/$AN$1,0) -> 705.40005 | AR12: =_xlfn.IFNA(H12/$AN$1,0) -> 52.346997
B13: Chocolate | C13: 0 | D13: ='Pastel Chocolate'!E12 -> 59.756374 | E13: 0 | F13: 0 | G13: 0 | H13: 0 | I13: =_xlfn.IFNA(C13/$J$1,0) -> 0 | J13: =_xlfn.IFNA(D13/$J$1,0) -> 132.79194 | K13: =_xlfn.IFNA(E13/$J$1,0) -> 0 | L13: =_xlfn.IFNA(F13/$J$1,0) -> 0 | M13: =_xlfn.IFNA(G13/$J$1,0) -> 0 | N13: =_xlfn.IFNA(H13/$J$1,0) -> 0 | O13: =_xlfn.IFNA(C13/$P$1,0) -> 0 | P13: =_xlfn.IFNA(D13/$P$1,0) -> 149.39094 | Q13: =_xlfn.IFNA(E13/$P$1,0) -> 0 | R13: =_xlfn.IFNA(F13/$P$1,0) -> 0 | S13: =_xlfn.IFNA(G13/$P$1,0) -> 0 | T13: =_xlfn.IFNA(H13/$P$1,0) -> 0 | U13: =_xlfn.IFNA(C13/$V$1,0) -> 0 | V13: =_xlfn.IFNA(D13/$V$1,0) -> 170.7325 | W13: =_xlfn.IFNA(E13/$V$1,0) -> 0 | X13: =_xlfn.IFNA(F13/$V$1,0) -> 0 | Y13: =_xlfn.IFNA(G13/$V$1,0) -> 0 | Z13: =_xlfn.IFNA(H13/$V$1,0) -> 0 | AA13: =_xlfn.IFNA(C13/$AB$1,0) -> 0 | AB13: =_xlfn.IFNA(D13/$AB$1,0) -> 199.18791 | AC13: =_xlfn.IFNA(E13/$AB$1,0) -> 0 | AD13: =_xlfn.IFNA(F13/$AB$1,0) -> 0 | AE13: =_xlfn.IFNA(G13/$AB$1,0) -> 0 | AF13: =_xlfn.IFNA(H13/$AB$1,0) -> 0 | AL13: 70 | AM13: =_xlfn.IFNA(C13/$AN$1,0) -> 0 | AN13: =_xlfn.IFNA(D13/$AN$1,0) -> 132.79194 | AO13: =_xlfn.IFNA(E13/$AN$1,0) -> 0 | AP13: =_xlfn.IFNA(F13/$AN$1,0) -> 0 | AQ13: =_xlfn.IFNA(G13/$AN$1,0) -> 0 | AR13: =_xlfn.IFNA(H13/$AN$1,0) -> 0
B14: Crunch | C14: 0 | D14: ='Pastel Crunch'!E14 -> 80.227256 | E14: ='Pastel Crunch'!F14 -> 166.4893 | F14: ='Pastel Crunch'!G14 -> 242.04424 | G14: ='Pastel Crunch'!H14 -> 338.62657 | H14: ='Pastel Crunch'!C14 -> 27.011564 | I14: =_xlfn.IFNA(C14/$J$1,0) -> 0 | J14: =_xlfn.IFNA(D14/$J$1,0) -> 178.28279 | K14: =_xlfn.IFNA(E14/$J$1,0) -> 369.97623 | L14: =_xlfn.IFNA(F14/$J$1,0) -> 537.87609 | M14: =_xlfn.IFNA(G14/$J$1,0) -> 752.50349 | N14: =_xlfn.IFNA(H14/$J$1,0) -> 60.025697 | O14: =_xlfn.IFNA(C14/$P$1,0) -> 0 | P14: =_xlfn.IFNA(D14/$P$1,0) -> 200.56814 | Q14: =_xlfn.IFNA(E14/$P$1,0) -> 416.22325 | R14: =_xlfn.IFNA(F14/$P$1,0) -> 605.1106 | S14: =_xlfn.IFNA(G14/$P$1,0) -> 846.56643 | T14: =_xlfn.IFNA(H14/$P$1,0) -> 67.52891 | U14: =_xlfn.IFNA(C14/$V$1,0) -> 0 | V14: =_xlfn.IFNA(D14/$V$1,0) -> 229.22073 | W14: =_xlfn.IFNA(E14/$V$1,0) -> 475.68372 | X14: =_xlfn.IFNA(F14/$V$1,0) -> 691.55497 | Y14: =_xlfn.IFNA(G14/$V$1,0) -> 967.50449 | Z14: =_xlfn.IFNA(H14/$V$1,0) -> 77.175897 | AA14: =_xlfn.IFNA(C14/$AB$1,0) -> 0 | AB14: =_xlfn.IFNA(D14/$AB$1,0) -> 267.42419 | AC14: =_xlfn.IFNA(E14/$AB$1,0) -> 554.96434 | AD14: =_xlfn.IFNA(F14/$AB$1,0) -> 806.81413 | AE14: =_xlfn.IFNA(G14/$AB$1,0) -> 1128.7552 | AF14: =_xlfn.IFNA(H14/$AB$1,0) -> 90.038546 | AH14: 185 | AI14: 360 | AJ14: 490 | AK14: 720 | AL14: 70 | AM14: =_xlfn.IFNA(C14/$AN$1,0) -> 0 | AN14: =_xlfn.IFNA(D14/$AN$1,0) -> 178.28279 | AO14: =_xlfn.IFNA(E14/$AN$1,0) -> 369.97623 | AP14: =_xlfn.IFNA(F14/$AN$1,0) -> 537.87609 | AQ14: =_xlfn.IFNA(G14/$AN$1,0) -> 752.50349 | AR14: =_xlfn.IFNA(H14/$AN$1,0) -> 60.025697
B15: Snicker's | C15: 0 | D15: ='Pastel Snicker''s'!E14 -> 33.131041 | E15: ='Pastel Snicker''s'!F14 -> 201.96184 | F15: ='Pastel Snicker''s'!G14 -> 281.62809 | G15: ='Pastel Snicker''s'!H14 -> 392.15336 | H15: ='Pastel Snicker''s'!C14 -> 30.969949 | I15: =_xlfn.IFNA(C15/$J$1,0) -> 0 | J15: =_xlfn.IFNA(D15/$J$1,0) -> 73.624534 | K15: =_xlfn.IFNA(E15/$J$1,0) -> 448.8041 | L15: =_xlfn.IFNA(F15/$J$1,0) -> 625.84019 | M15: =_xlfn.IFNA(G15/$J$1,0) -> 871.45192 | N15: =_xlfn.IFNA(H15/$J$1,0) -> 68.822108 | O15: =_xlfn.IFNA(C15/$P$1,0) -> 0 | P15: =_xlfn.IFNA(D15/$P$1,0) -> 82.827601 | Q15: =_xlfn.IFNA(E15/$P$1,0) -> 504.90461 | R15: =_xlfn.IFNA(F15/$P$1,0) -> 704.07022 | S15: =_xlfn.IFNA(G15/$P$1,0) -> 980.38341 | T15: =_xlfn.IFNA(H15/$P$1,0) -> 77.424872 | U15: =_xlfn.IFNA(C15/$V$1,0) -> 0 | V15: =_xlfn.IFNA(D15/$V$1,0) -> 94.660116 | W15: =_xlfn.IFNA(E15/$V$1,0) -> 577.03384 | X15: =_xlfn.IFNA(F15/$V$1,0) -> 804.65168 | Y15: =_xlfn.IFNA(G15/$V$1,0) -> 1120.4382 | Z15: =_xlfn.IFNA(H15/$V$1,0) -> 88.485568 | AA15: =_xlfn.IFNA(C15/$AB$1,0) -> 0 | AB15: =_xlfn.IFNA(D15/$AB$1,0) -> 110.4368 | AC15: =_xlfn.IFNA(E15/$AB$1,0) -> 673.20614 | AD15: =_xlfn.IFNA(F15/$AB$1,0) -> 938.76029 | AE15: =_xlfn.IFNA(G15/$AB$1,0) -> 1307.1779 | AF15: =_xlfn.IFNA(H15/$AB$1,0) -> 103.23316 | AI15: 400 | AJ15: 500 | AK15: 750 | AL15: 70 | AM15: =_xlfn.IFNA(C15/$AN$1,0) -> 0 | AN15: =_xlfn.IFNA(D15/$AN$1,0) -> 73.624534 | AO15: =_xlfn.IFNA(E15/$AN$1,0) -> 448.8041 | AP15: =_xlfn.IFNA(F15/$AN$1,0) -> 625.84019 | AQ15: =_xlfn.IFNA(G15/$AN$1,0) -> 871.45192 | AR15: =_xlfn.IFNA(H15/$AN$1,0) -> 68.822108
B16: Dulce de Leche | C16: 0 | D16: ='Pastel Vainilla'!E12 -> 0 | E16: ='Pastel Vainilla'!F12 -> 146.8559 | F16: ='Pastel Vainilla'!G12 -> 205.71168 | G16: ='Pastel Vainilla'!H12 -> 330.05251 | H16: ='Pastel Vainilla'!C12 -> 17.49273 | I16: =_xlfn.IFNA(C16/$J$1,0) -> 0 | J16: =_xlfn.IFNA(D16/$J$1,0) -> 0 | K16: =_xlfn.IFNA(E16/$J$1,0) -> 326.34644 | L16: =_xlfn.IFNA(F16/$J$1,0) -> 457.13706 | M16: =_xlfn.IFNA(G16/$J$1,0) -> 733.45002 | N16: =_xlfn.IFNA(H16/$J$1,0) -> 38.872733 | O16: =_xlfn.IFNA(C16/$P$1,0) -> 0 | P16: =_xlfn.IFNA(D16/$P$1,0) -> 0 | Q16: =_xlfn.IFNA(E16/$P$1,0) -> 367.13975 | R16: =_xlfn.IFNA(F16/$P$1,0) -> 514.27919 | S16: =_xlfn.IFNA(G16/$P$1,0) -> 825.13128 | T16: =_xlfn.IFNA(H16/$P$1,0) -> 43.731825 | U16: =_xlfn.IFNA(C16/$V$1,0) -> 0 | V16: =_xlfn.IFNA(D16/$V$1,0) -> 0 | W16: =_xlfn.IFNA(E16/$V$1,0) -> 419.58828 | X16: =_xlfn.IFNA(F16/$V$1,0) -> 587.74764 | Y16: =_xlfn.IFNA(G16/$V$1,0) -> 943.00717 | Z16: =_xlfn.IFNA(H16/$V$1,0) -> 49.979228 | AA16: =_xlfn.IFNA(C16/$AB$1,0) -> 0 | AB16: =_xlfn.IFNA(D16/$AB$1,0) -> 0 | AC16: =_xlfn.IFNA(E16/$AB$1,0) -> 489.51966 | AD16: =_xlfn.IFNA(F16/$AB$1,0) -> 685.70559 | AE16: =_xlfn.IFNA(G16/$AB$1,0) -> 1100.175 | AF16: =_xlfn.IFNA(H16/$AB$1,0) -> 58.3091 | AI16: 340 | AJ16: 450 | AK16: 710 | AL16: 70 | AM16: =_xlfn.IFNA(C16/$AN$1,0) -> 0 | AN16: =_xlfn.IFNA(D16/$AN$1,0) -> 0 | AO16: =_xlfn.IFNA(E16/$AN$1,0) -> 326.34644 | AP16: =_xlfn.IFNA(F16/$AN$1,0) -> 457.13706 | AQ16: =_xlfn.IFNA(G16/$AN$1,0) -> 733.45002 | AR16: =_xlfn.IFNA(H16/$AN$1,0) -> 38.872733
B17: 3 Leches | C17: ='Pastel 3 Leches'!F13 -> 31.019912 | D17: 0 | E17: 0 | F17: ='Pastel 3 Leches'!D13 -> 176.71615 | G17: ='Pastel 3 Leches'!E13 -> 401.53172 | H17: ='Pastel 3 Leches'!C13 -> 32.259831 | I17: =_xlfn.IFNA(C17/$J$1,0) -> 68.933139 | J17: =_xlfn.IFNA(D17/$J$1,0) -> 0 | K17: =_xlfn.IFNA(E17/$J$1,0) -> 0 | L17: =_xlfn.IFNA(F17/$J$1,0) -> 392.70255 | M17: =_xlfn.IFNA(G17/$J$1,0) -> 892.29271 | N17: =_xlfn.IFNA(H17/$J$1,0) -> 71.688514 | O17: =_xlfn.IFNA(C17/$P$1,0) -> 77.549781 | P17: =_xlfn.IFNA(D17/$P$1,0) -> 0 | Q17: =_xlfn.IFNA(E17/$P$1,0) -> 0 | R17: =_xlfn.IFNA(F17/$P$1,0) -> 441.79037 | S17: =_xlfn.IFNA(G17/$P$1,0) -> 1003.8293 | T17: =_xlfn.IFNA(H17/$P$1,0) -> 80.649579 | U17: =_xlfn.IFNA(C17/$V$1,0) -> 88.628321 | V17: =_xlfn.IFNA(D17/$V$1,0) -> 0 | W17: =_xlfn.IFNA(E17/$V$1,0) -> 0 | X17: =_xlfn.IFNA(F17/$V$1,0) -> 504.90328 | Y17: =_xlfn.IFNA(G17/$V$1,0) -> 1147.2335 | Z17: =_xlfn.IFNA(H17/$V$1,0) -> 92.170947 | AA17: =_xlfn.IFNA(C17/$AB$1,0) -> 103.39971 | AB17: =_xlfn.IFNA(D17/$AB$1,0) -> 0 | AC17: =_xlfn.IFNA(E17/$AB$1,0) -> 0 | AD17: =_xlfn.IFNA(F17/$AB$1,0) -> 589.05383 | AE17: =_xlfn.IFNA(G17/$AB$1,0) -> 1338.4391 | AF17: =_xlfn.IFNA(H17/$AB$1,0) -> 107.53277 | AI17: =-AI17 -> 0 | AJ17: 435 | AK17: =-AK17 -> 0 | AL17: 75 | AM17: =_xlfn.IFNA(C17/$AN$1,0) -> 68.933139 | AN17: =_xlfn.IFNA(D17/$AN$1,0) -> 0 | AO17: =_xlfn.IFNA(E17/$AN$1,0) -> 0 | AP17: =_xlfn.IFNA(F17/$AN$1,0) -> 392.70255 | AQ17: =_xlfn.IFNA(G17/$AN$1,0) -> 892.29271 | AR17: =_xlfn.IFNA(H17/$AN$1,0) -> 71.688514
B18: 3 Leches Lotus | C18: ='Pastel 3 Leches Lotus'!F14 -> 41.38822 | F18: ='Pastel 3 Leches Lotus'!D14 -> 188.12781 | G18: ='Pastel 3 Leches Lotus'!E14 -> 504.65497 | H18: ='Pastel 3 Leches Lotus'!C14 -> 34.161774 | I18: =_xlfn.IFNA(C18/$J$1,0) -> 91.973822 | J18: =_xlfn.IFNA(D18/$J$1,0) -> 0 | K18: =_xlfn.IFNA(E18/$J$1,0) -> 0 | L18: =_xlfn.IFNA(F18/$J$1,0) -> 418.06179 | M18: =_xlfn.IFNA(G18/$J$1,0) -> 1121.4555 | N18: =_xlfn.IFNA(H18/$J$1,0) -> 75.915054 | O18: =_xlfn.IFNA(C18/$P$1,0) -> 103.47055 | P18: =_xlfn.IFNA(D18/$P$1,0) -> 0 | Q18: =_xlfn.IFNA(E18/$P$1,0) -> 0 | R18: =_xlfn.IFNA(F18/$P$1,0) -> 470.31951 | S18: =_xlfn.IFNA(G18/$P$1,0) -> 1261.6374 | T18: =_xlfn.IFNA(H18/$P$1,0) -> 85.404436 | U18: =_xlfn.IFNA(C18/$V$1,0) -> 118.25206 | V18: =_xlfn.IFNA(D18/$V$1,0) -> 0 | W18: =_xlfn.IFNA(E18/$V$1,0) -> 0 | X18: =_xlfn.IFNA(F18/$V$1,0) -> 537.50802 | Y18: =_xlfn.IFNA(G18/$V$1,0) -> 1441.8713 | Z18: =_xlfn.IFNA(H18/$V$1,0) -> 97.605069 | AA18: =_xlfn.IFNA(C18/$AB$1,0) -> 137.96073 | AB18: =_xlfn.IFNA(D18/$AB$1,0) -> 0 | AC18: =_xlfn.IFNA(E18/$AB$1,0) -> 0 | AD18: =_xlfn.IFNA(F18/$AB$1,0) -> 627.09269 | AE18: =_xlfn.IFNA(G18/$AB$1,0) -> 1682.1832 | AF18: =_xlfn.IFNA(H18/$AB$1,0) -> 113.87258 | AI18: =-AI18 -> 0 | AJ18: 480 | AK18: =-AK18 -> 0 | AL18: 80 | AM18: =_xlfn.IFNA(C18/$AN$1,0) -> 91.973822 | AN18: =_xlfn.IFNA(D18/$AN$1,0) -> 0 | AO18: =_xlfn.IFNA(E18/$AN$1,0) -> 0 | AP18: =_xlfn.IFNA(F18/$AN$1,0) -> 418.06179 | AQ18: =_xlfn.IFNA(G18/$AN$1,0) -> 1121.4555 | AR18: =_xlfn.IFNA(H18/$AN$1,0) -> 75.915054
B19: Flan | C19: ='Resumen Costos'!C19 -> 22.94585 | D19: ='Resumen Costos'!D19 -> 0 | E19: ='Resumen Costos'!E19 -> 0 | F19: ='Resumen Costos'!F19 -> 241.70639 | G19: ='Resumen Costos'!G19 -> 0 | H19: ='Resumen Costos'!H19 -> 0 | I19: =_xlfn.IFNA(C19/$J$1,0) -> 50.990777 | J19: =_xlfn.IFNA(D19/$J$1,0) -> 0 | K19: =_xlfn.IFNA(E19/$J$1,0) -> 0 | L19: =_xlfn.IFNA(F19/$J$1,0) -> 537.1253 | M19: =_xlfn.IFNA(G19/$J$1,0) -> 0 | N19: =_xlfn.IFNA(H19/$J$1,0) -> 0 | O19: =_xlfn.IFNA(C19/$P$1,0) -> 57.364624 | P19: =_xlfn.IFNA(D19/$P$1,0) -> 0 | Q19: =_xlfn.IFNA(E19/$P$1,0) -> 0 | R19: =_xlfn.IFNA(F19/$P$1,0) -> 604.26596 | S19: =_xlfn.IFNA(G19/$P$1,0) -> 0 | T19: =_xlfn.IFNA(H19/$P$1,0) -> 0 | U19: =_xlfn.IFNA(C19/$V$1,0) -> 65.55957 | V19: =_xlfn.IFNA(D19/$V$1,0) -> 0 | W19: =_xlfn.IFNA(E19/$V$1,0) -> 0 | X19: =_xlfn.IFNA(F19/$V$1,0) -> 690.58967 | Y19: =_xlfn.IFNA(G19/$V$1,0) -> 0 | Z19: =_xlfn.IFNA(H19/$V$1,0) -> 0 | AA19: =_xlfn.IFNA(C19/$AB$1,0) -> 76.486165 | AB19: =_xlfn.IFNA(D19/$AB$1,0) -> 0 | AC19: =_xlfn.IFNA(E19/$AB$1,0) -> 0 | AD19: =_xlfn.IFNA(F19/$AB$1,0) -> 805.68795 | AE19: =_xlfn.IFNA(G19/$AB$1,0) -> 0 | AF19: =_xlfn.IFNA(H19/$AB$1,0) -> 0 | AG19: 55 | AM19: =_xlfn.IFNA(C19/$AN$1,0) -> 50.990777 | AN19: =_xlfn.IFNA(D19/$AN$1,0) -> 0 | AO19: =_xlfn.IFNA(E19/$AN$1,0) -> 0 | AP19: =_xlfn.IFNA(F19/$AN$1,0) -> 537.1253 | AQ19: =_xlfn.IFNA(G19/$AN$1,0) -> 0 | AR19: =_xlfn.IFNA(H19/$AN$1,0) -> 0
A20: Vasos | B20: Fresas con crema | D20: =Vasos!D24 -> 17.018195 | E20: =Vasos!C24 -> 32.405495 | F20: =Vasos!E24 -> 39.465763 | G20: =Vasos!F24 -> 43.147207 | I20: =_xlfn.IFNA(C20/$J$1,0) -> 0 | J20: =_xlfn.IFNA(D20/$J$1,0) -> 37.818211 | K20: =_xlfn.IFNA(E20/$J$1,0) -> 72.012211 | L20: =_xlfn.IFNA(F20/$J$1,0) -> 87.701696 | M20: =_xlfn.IFNA(G20/$J$1,0) -> 95.882681 | N20: =_xlfn.IFNA(H20/$J$1,0) -> 0 | O20: =_xlfn.IFNA(C20/$P$1,0) -> 0 | P20: =_xlfn.IFNA(D20/$P$1,0) -> 42.545487 | Q20: =_xlfn.IFNA(E20/$P$1,0) -> 81.013738 | R20: =_xlfn.IFNA(F20/$P$1,0) -> 98.664408 | S20: =_xlfn.IFNA(G20/$P$1,0) -> 107.86802 | T20: =_xlfn.IFNA(H20/$P$1,0) -> 0 | U20: =_xlfn.IFNA(C20/$V$1,0) -> 0 | V20: =_xlfn.IFNA(D20/$V$1,0) -> 48.623414 | W20: =_xlfn.IFNA(E20/$V$1,0) -> 92.587129 | X20: =_xlfn.IFNA(F20/$V$1,0) -> 112.75932 | Y20: =_xlfn.IFNA(G20/$V$1,0) -> 123.27773 | Z20: =_xlfn.IFNA(H20/$V$1,0) -> 0 | AA20: =_xlfn.IFNA(C20/$AB$1,0) -> 0 | AB20: =_xlfn.IFNA(D20/$AB$1,0) -> 56.727316 | AC20: =_xlfn.IFNA(E20/$AB$1,0) -> 108.01832 | AD20: =_xlfn.IFNA(F20/$AB$1,0) -> 131.55254 | AE20: =_xlfn.IFNA(G20/$AB$1,0) -> 143.82402 | AF20: =_xlfn.IFNA(H20/$AB$1,0) -> 0 | AH20: 60 | AI20: 90 | AJ20: 105 | AK20: 115 | AM20: =_xlfn.IFNA(C20/$AN$1,0) -> 0 | AN20: =_xlfn.IFNA(D20/$AN$1,0) -> 37.818211 | AO20: =_xlfn.IFNA(E20/$AN$1,0) -> 72.012211 | AP20: =_xlfn.IFNA(F20/$AN$1,0) -> 87.701696 | AQ20: =_xlfn.IFNA(G20/$AN$1,0) -> 95.882681 | AR20: =_xlfn.IFNA(H20/$AN$1,0) -> 0
B21: Fresas con pay | D21: =Vasos!D25 -> 29.233566 | G21: =Vasos!C25 -> 44.620867 | I21: =_xlfn.IFNA(C21/$J$1,0) -> 0 | J21: =_xlfn.IFNA(D21/$J$1,0) -> 64.963481 | K21: =_xlfn.IFNA(E21/$J$1,0) -> 0 | L21: =_xlfn.IFNA(F21/$J$1,0) -> 0 | M21: =_xlfn.IFNA(G21/$J$1,0) -> 99.157481 | N21: =_xlfn.IFNA(H21/$J$1,0) -> 0 | O21: =_xlfn.IFNA(C21/$P$1,0) -> 0 | P21: =_xlfn.IFNA(D21/$P$1,0) -> 73.083916 | Q21: =_xlfn.IFNA(E21/$P$1,0) -> 0 | R21: =_xlfn.IFNA(F21/$P$1,0) -> 0 | S21: =_xlfn.IFNA(G21/$P$1,0) -> 111.55217 | T21: =_xlfn.IFNA(H21/$P$1,0) -> 0 | U21: =_xlfn.IFNA(C21/$V$1,0) -> 0 | V21: =_xlfn.IFNA(D21/$V$1,0) -> 83.524475 | W21: =_xlfn.IFNA(E21/$V$1,0) -> 0 | X21: =_xlfn.IFNA(F21/$V$1,0) -> 0 | Y21: =_xlfn.IFNA(G21/$V$1,0) -> 127.48819 | Z21: =_xlfn.IFNA(H21/$V$1,0) -> 0 | AA21: =_xlfn.IFNA(C21/$AB$1,0) -> 0 | AB21: =_xlfn.IFNA(D21/$AB$1,0) -> 97.445221 | AC21: =_xlfn.IFNA(E21/$AB$1,0) -> 0 | AD21: =_xlfn.IFNA(F21/$AB$1,0) -> 0 | AE21: =_xlfn.IFNA(G21/$AB$1,0) -> 148.73622 | AF21: =_xlfn.IFNA(H21/$AB$1,0) -> 0 | AM21: =_xlfn.IFNA(C21/$AN$1,0) -> 0 | AN21: =_xlfn.IFNA(D21/$AN$1,0) -> 64.963481 | AO21: =_xlfn.IFNA(E21/$AN$1,0) -> 0 | AP21: =_xlfn.IFNA(F21/$AN$1,0) -> 0 | AQ21: =_xlfn.IFNA(G21/$AN$1,0) -> 99.157481 | AR21: =_xlfn.IFNA(H21/$AN$1,0) -> 0
B22: Crema | D22: =Vasos!D26 -> 9.8099053 | G22: =Vasos!C26 -> 17.08788 | I22: =_xlfn.IFNA(C22/$J$1,0) -> 0 | J22: =_xlfn.IFNA(D22/$J$1,0) -> 21.79979 | K22: =_xlfn.IFNA(E22/$J$1,0) -> 0 | L22: =_xlfn.IFNA(F22/$J$1,0) -> 0 | M22: =_xlfn.IFNA(G22/$J$1,0) -> 37.973066 | N22: =_xlfn.IFNA(H22/$J$1,0) -> 0 | O22: =_xlfn.IFNA(C22/$P$1,0) -> 0 | P22: =_xlfn.IFNA(D22/$P$1,0) -> 24.524763 | Q22: =_xlfn.IFNA(E22/$P$1,0) -> 0 | R22: =_xlfn.IFNA(F22/$P$1,0) -> 0 | S22: =_xlfn.IFNA(G22/$P$1,0) -> 42.7197 | T22: =_xlfn.IFNA(H22/$P$1,0) -> 0 | U22: =_xlfn.IFNA(C22/$V$1,0) -> 0 | V22: =_xlfn.IFNA(D22/$V$1,0) -> 28.028301 | W22: =_xlfn.IFNA(E22/$V$1,0) -> 0 | X22: =_xlfn.IFNA(F22/$V$1,0) -> 0 | Y22: =_xlfn.IFNA(G22/$V$1,0) -> 48.822514 | Z22: =_xlfn.IFNA(H22/$V$1,0) -> 0 | AA22: =_xlfn.IFNA(C22/$AB$1,0) -> 0 | AB22: =_xlfn.IFNA(D22/$AB$1,0) -> 32.699684 | AC22: =_xlfn.IFNA(E22/$AB$1,0) -> 0 | AD22: =_xlfn.IFNA(F22/$AB$1,0) -> 0 | AE22: =_xlfn.IFNA(G22/$AB$1,0) -> 56.9596 | AF22: =_xlfn.IFNA(H22/$AB$1,0) -> 0 | AM22: =_xlfn.IFNA(C22/$AN$1,0) -> 0 | AN22: =_xlfn.IFNA(D22/$AN$1,0) -> 21.79979 | AO22: =_xlfn.IFNA(E22/$AN$1,0) -> 0 | AP22: =_xlfn.IFNA(F22/$AN$1,0) -> 0 | AQ22: =_xlfn.IFNA(G22/$AN$1,0) -> 37.973066 | AR22: =_xlfn.IFNA(H22/$AN$1,0) -> 0
A23: Bollos | B23: Chocolate | C23: =Bollos!D14 -> 14.435269 | D23: ='Pastel Fresas Con Crema'!E24 -> 0 | E23: ='Pastel Fresas Con Crema'!F24 -> 0 | F23: ='Pastel Fresas Con Crema'!G24 -> 0 | G23: ='Pastel Fresas Con Crema'!H24 -> 0 | H23: ='Pastel Fresas Con Crema'!C24 -> 0 | I23: =_xlfn.IFNA(C23/$J$1,0) -> 32.078376 | J23: =_xlfn.IFNA(D23/$J$1,0) -> 0 | K23: =_xlfn.IFNA(E23/$J$1,0) -> 0 | L23: =_xlfn.IFNA(F23/$J$1,0) -> 0 | M23: =_xlfn.IFNA(G23/$J$1,0) -> 0 | N23: =_xlfn.IFNA(H23/$J$1,0) -> 0 | O23: =_xlfn.IFNA(C23/$P$1,0) -> 36.088173 | P23: =_xlfn.IFNA(D23/$P$1,0) -> 0 | Q23: =_xlfn.IFNA(E23/$P$1,0) -> 0 | R23: =_xlfn.IFNA(F23/$P$1,0) -> 0 | S23: =_xlfn.IFNA(G23/$P$1,0) -> 0 | T23: =_xlfn.IFNA(H23/$P$1,0) -> 0 | U23: =_xlfn.IFNA(C23/$V$1,0) -> 41.243626 | V23: =_xlfn.IFNA(D23/$V$1,0) -> 0 | W23: =_xlfn.IFNA(E23/$V$1,0) -> 0 | X23: =_xlfn.IFNA(F23/$V$1,0) -> 0 | Y23: =_xlfn.IFNA(G23/$V$1,0) -> 0 | Z23: =_xlfn.IFNA(H23/$V$1,0) -> 0 | AA23: =_xlfn.IFNA(C23/$AB$1,0) -> 48.117564 | AB23: =_xlfn.IFNA(D23/$AB$1,0) -> 0 | AC23: =_xlfn.IFNA(E23/$AB$1,0) -> 0 | AD23: =_xlfn.IFNA(F23/$AB$1,0) -> 0 | AE23: =_xlfn.IFNA(G23/$AB$1,0) -> 0 | AF23: =_xlfn.IFNA(H23/$AB$1,0) -> 0 | AG23: 36 | AM23: =_xlfn.IFNA(C23/$AN$1,0) -> 32.078376 | AN23: =_xlfn.IFNA(D23/$AN$1,0) -> 0 | AO23: =_xlfn.IFNA(E23/$AN$1,0) -> 0 | AP23: =_xlfn.IFNA(F23/$AN$1,0) -> 0 | AQ23: =_xlfn.IFNA(G23/$AN$1,0) -> 0 | AR23: =_xlfn.IFNA(H23/$AN$1,0) -> 0
B24: Vainilla | C24: =Bollos!C14 -> 12.485675 | I24: =_xlfn.IFNA(C24/$J$1,0) -> 27.745944 | J24: =_xlfn.IFNA(D24/$J$1,0) -> 0 | K24: =_xlfn.IFNA(E24/$J$1,0) -> 0 | L24: =_xlfn.IFNA(F24/$J$1,0) -> 0 | M24: =_xlfn.IFNA(G24/$J$1,0) -> 0 | N24: =_xlfn.IFNA(H24/$J$1,0) -> 0 | O24: =_xlfn.IFNA(C24/$P$1,0) -> 31.214187 | P24: =_xlfn.IFNA(D24/$P$1,0) -> 0 | Q24: =_xlfn.IFNA(E24/$P$1,0) -> 0 | R24: =_xlfn.IFNA(F24/$P$1,0) -> 0 | S24: =_xlfn.IFNA(G24/$P$1,0) -> 0 | T24: =_xlfn.IFNA(H24/$P$1,0) -> 0 | U24: =_xlfn.IFNA(C24/$V$1,0) -> 35.673357 | V24: =_xlfn.IFNA(D24/$V$1,0) -> 0 | W24: =_xlfn.IFNA(E24/$V$1,0) -> 0 | X24: =_xlfn.IFNA(F24/$V$1,0) -> 0 | Y24: =_xlfn.IFNA(G24/$V$1,0) -> 0 | Z24: =_xlfn.IFNA(H24/$V$1,0) -> 0 | AA24: =_xlfn.IFNA(C24/$AB$1,0) -> 41.618916 | AB24: =_xlfn.IFNA(D24/$AB$1,0) -> 0 | AC24: =_xlfn.IFNA(E24/$AB$1,0) -> 0 | AD24: =_xlfn.IFNA(F24/$AB$1,0) -> 0 | AE24: =_xlfn.IFNA(G24/$AB$1,0) -> 0 | AF24: =_xlfn.IFNA(H24/$AB$1,0) -> 0 | AG24: 34 | AM24: =_xlfn.IFNA(C24/$AN$1,0) -> 27.745944 | AN24: =_xlfn.IFNA(D24/$AN$1,0) -> 0 | AO24: =_xlfn.IFNA(E24/$AN$1,0) -> 0 | AP24: =_xlfn.IFNA(F24/$AN$1,0) -> 0 | AQ24: =_xlfn.IFNA(G24/$AN$1,0) -> 0 | AR24: =_xlfn.IFNA(H24/$AN$1,0) -> 0
B25: Zanahoria | C25: =Bollos!F14 -> 12.928453 | D25: 0 | E25: ='Pastel Zanahoria'!F21 -> 0 | F25: ='Pastel Zanahoria'!G21 -> 0 | G25: ='Pastel Zanahoria'!H21 -> 0 | H25: ='Pastel Zanahoria'!C21 -> 0 | I25: =_xlfn.IFNA(C25/$J$1,0) -> 28.729896 | J25: =_xlfn.IFNA(D25/$J$1,0) -> 0 | K25: =_xlfn.IFNA(E25/$J$1,0) -> 0 | L25: =_xlfn.IFNA(F25/$J$1,0) -> 0 | M25: =_xlfn.IFNA(G25/$J$1,0) -> 0 | N25: =_xlfn.IFNA(H25/$J$1,0) -> 0 | O25: =_xlfn.IFNA(C25/$P$1,0) -> 32.321133 | P25: =_xlfn.IFNA(D25/$P$1,0) -> 0 | Q25: =_xlfn.IFNA(E25/$P$1,0) -> 0 | R25: =_xlfn.IFNA(F25/$P$1,0) -> 0 | S25: =_xlfn.IFNA(G25/$P$1,0) -> 0 | T25: =_xlfn.IFNA(H25/$P$1,0) -> 0 | U25: =_xlfn.IFNA(C25/$V$1,0) -> 36.938438 | V25: =_xlfn.IFNA(D25/$V$1,0) -> 0 | W25: =_xlfn.IFNA(E25/$V$1,0) -> 0 | X25: =_xlfn.IFNA(F25/$V$1,0) -> 0 | Y25: =_xlfn.IFNA(G25/$V$1,0) -> 0 | Z25: =_xlfn.IFNA(H25/$V$1,0) -> 0 | AA25: =_xlfn.IFNA(C25/$AB$1,0) -> 43.094844 | AB25: =_xlfn.IFNA(D25/$AB$1,0) -> 0 | AC25: =_xlfn.IFNA(E25/$AB$1,0) -> 0 | AD25: =_xlfn.IFNA(F25/$AB$1,0) -> 0 | AE25: =_xlfn.IFNA(G25/$AB$1,0) -> 0 | AF25: =_xlfn.IFNA(H25/$AB$1,0) -> 0 | AG25: 27 | AM25: =_xlfn.IFNA(C25/$AN$1,0) -> 28.729896 | AN25: =_xlfn.IFNA(D25/$AN$1,0) -> 0 | AO25: =_xlfn.IFNA(E25/$AN$1,0) -> 0 | AP25: =_xlfn.IFNA(F25/$AN$1,0) -> 0 | AQ25: =_xlfn.IFNA(G25/$AN$1,0) -> 0 | AR25: =_xlfn.IFNA(H25/$AN$1,0) -> 0
B26: Red Velvet | C26: =Bollos!E14 -> 13.970433 | D26: ='Pastel Chocolate'!E24 -> 0 | E26: ='Pastel Chocolate'!F24 -> 0 | F26: ='Pastel Chocolate'!G24 -> 0 | G26: ='Pastel Chocolate'!H24 -> 0 | H26: ='Pastel Chocolate'!C24 -> 0 | I26: =_xlfn.IFNA(C26/$J$1,0) -> 31.045406 | J26: =_xlfn.IFNA(D26/$J$1,0) -> 0 | K26: =_xlfn.IFNA(E26/$J$1,0) -> 0 | L26: =_xlfn.IFNA(F26/$J$1,0) -> 0 | M26: =_xlfn.IFNA(G26/$J$1,0) -> 0 | N26: =_xlfn.IFNA(H26/$J$1,0) -> 0 | O26: =_xlfn.IFNA(C26/$P$1,0) -> 34.926082 | P26: =_xlfn.IFNA(D26/$P$1,0) -> 0 | Q26: =_xlfn.IFNA(E26/$P$1,0) -> 0 | R26: =_xlfn.IFNA(F26/$P$1,0) -> 0 | S26: =_xlfn.IFNA(G26/$P$1,0) -> 0 | T26: =_xlfn.IFNA(H26/$P$1,0) -> 0 | U26: =_xlfn.IFNA(C26/$V$1,0) -> 39.915522 | V26: =_xlfn.IFNA(D26/$V$1,0) -> 0 | W26: =_xlfn.IFNA(E26/$V$1,0) -> 0 | X26: =_xlfn.IFNA(F26/$V$1,0) -> 0 | Y26: =_xlfn.IFNA(G26/$V$1,0) -> 0 | Z26: =_xlfn.IFNA(H26/$V$1,0) -> 0 | AA26: =_xlfn.IFNA(C26/$AB$1,0) -> 46.568109 | AB26: =_xlfn.IFNA(D26/$AB$1,0) -> 0 | AC26: =_xlfn.IFNA(E26/$AB$1,0) -> 0 | AD26: =_xlfn.IFNA(F26/$AB$1,0) -> 0 | AE26: =_xlfn.IFNA(G26/$AB$1,0) -> 0 | AF26: =_xlfn.IFNA(H26/$AB$1,0) -> 0 | AG26: 30 | AM26: =_xlfn.IFNA(C26/$AN$1,0) -> 31.045406 | AN26: =_xlfn.IFNA(D26/$AN$1,0) -> 0 | AO26: =_xlfn.IFNA(E26/$AN$1,0) -> 0 | AP26: =_xlfn.IFNA(F26/$AN$1,0) -> 0 | AQ26: =_xlfn.IFNA(G26/$AN$1,0) -> 0 | AR26: =_xlfn.IFNA(H26/$AN$1,0) -> 0
B27: Lotus | C27: =Bollos!G14 -> 20.155525 | D27: 0 | E27: 0 | F27: 0 | G27: 0 | H27: 0 | I27: =_xlfn.IFNA(C27/$J$1,0) -> 44.790056 | J27: =_xlfn.IFNA(D27/$J$1,0) -> 0 | K27: =_xlfn.IFNA(E27/$J$1,0) -> 0 | L27: =_xlfn.IFNA(F27/$J$1,0) -> 0 | M27: =_xlfn.IFNA(G27/$J$1,0) -> 0 | N27: =_xlfn.IFNA(H27/$J$1,0) -> 0 | O27: =_xlfn.IFNA(C27/$P$1,0) -> 50.388813 | P27: =_xlfn.IFNA(D27/$P$1,0) -> 0 | Q27: =_xlfn.IFNA(E27/$P$1,0) -> 0 | R27: =_xlfn.IFNA(F27/$P$1,0) -> 0 | S27: =_xlfn.IFNA(G27/$P$1,0) -> 0 | T27: =_xlfn.IFNA(H27/$P$1,0) -> 0 | U27: =_xlfn.IFNA(C27/$V$1,0) -> 57.587215 | V27: =_xlfn.IFNA(D27/$V$1,0) -> 0 | W27: =_xlfn.IFNA(E27/$V$1,0) -> 0 | X27: =_xlfn.IFNA(F27/$V$1,0) -> 0 | Y27: =_xlfn.IFNA(G27/$V$1,0) -> 0 | Z27: =_xlfn.IFNA(H27/$V$1,0) -> 0 | AA27: =_xlfn.IFNA(C27/$AB$1,0) -> 67.185084 | AB27: =_xlfn.IFNA(D27/$AB$1,0) -> 0 | AC27: =_xlfn.IFNA(E27/$AB$1,0) -> 0 | AD27: =_xlfn.IFNA(F27/$AB$1,0) -> 0 | AE27: =_xlfn.IFNA(G27/$AB$1,0) -> 0 | AF27: =_xlfn.IFNA(H27/$AB$1,0) -> 0 | AG27: 39 | AM27: =_xlfn.IFNA(C27/$AN$1,0) -> 44.790056 | AN27: =_xlfn.IFNA(D27/$AN$1,0) -> 0 | AO27: =_xlfn.IFNA(E27/$AN$1,0) -> 0 | AP27: =_xlfn.IFNA(F27/$AN$1,0) -> 0 | AQ27: =_xlfn.IFNA(G27/$AN$1,0) -> 0 | AR27: =_xlfn.IFNA(H27/$AN$1,0) -> 0
A28: Cheesecake | B28: Lotus | C28: ='Resumen Costos'!C28 -> 60.99483 | D28: ='Resumen Costos'!D28 -> 0 | E28: ='Resumen Costos'!E28 -> 205.30523 | F28: ='Resumen Costos'!F28 -> 319.64719 | G28: ='Resumen Costos'!G28 -> 0 | H28: ='Resumen Costos'!H28 -> 0 | I28: =_xlfn.IFNA(C28/$J$1,0) -> 135.54407 | J28: =_xlfn.IFNA(D28/$J$1,0) -> 0 | K28: =_xlfn.IFNA(E28/$J$1,0) -> 456.23384 | L28: =_xlfn.IFNA(F28/$J$1,0) -> 710.32709 | M28: =_xlfn.IFNA(G28/$J$1,0) -> 0 | N28: =_xlfn.IFNA(H28/$J$1,0) -> 0 | O28: =_xlfn.IFNA(C28/$P$1,0) -> 152.48707 | P28: =_xlfn.IFNA(D28/$P$1,0) -> 0 | Q28: =_xlfn.IFNA(E28/$P$1,0) -> 513.26306 | R28: =_xlfn.IFNA(F28/$P$1,0) -> 799.11797 | S28: =_xlfn.IFNA(G28/$P$1,0) -> 0 | T28: =_xlfn.IFNA(H28/$P$1,0) -> 0 | U28: =_xlfn.IFNA(C28/$V$1,0) -> 174.27094 | V28: =_xlfn.IFNA(D28/$V$1,0) -> 0 | W28: =_xlfn.IFNA(E28/$V$1,0) -> 586.58636 | X28: =_xlfn.IFNA(F28/$V$1,0) -> 913.27768 | Y28: =_xlfn.IFNA(G28/$V$1,0) -> 0 | Z28: =_xlfn.IFNA(H28/$V$1,0) -> 0 | AA28: =_xlfn.IFNA(C28/$AB$1,0) -> 203.3161 | AB28: =_xlfn.IFNA(D28/$AB$1,0) -> 0 | AC28: =_xlfn.IFNA(E28/$AB$1,0) -> 684.35075 | AD28: =_xlfn.IFNA(F28/$AB$1,0) -> 1065.4906 | AE28: =_xlfn.IFNA(G28/$AB$1,0) -> 0 | AF28: =_xlfn.IFNA(H28/$AB$1,0) -> 0 | AG28: 135 | AJ28: 650 | AM28: =_xlfn.IFNA(C28/$AN$1,0) -> 135.54407 | AN28: =_xlfn.IFNA(D28/$AN$1,0) -> 0 | AO28: =_xlfn.IFNA(E28/$AN$1,0) -> 456.23384 | AP28: =_xlfn.IFNA(F28/$AN$1,0) -> 710.32709 | AQ28: =_xlfn.IFNA(G28/$AN$1,0) -> 0 | AR28: =_xlfn.IFNA(H28/$AN$1,0) -> 0
B29: Tortuga | C29: ='Resumen Costos'!C29 -> 52.683417 | D29: ='Resumen Costos'!D29 -> 0 | E29: ='Resumen Costos'!E29 -> 182.33088 | F29: ='Resumen Costos'!F29 -> 254.16219 | G29: ='Resumen Costos'!G29 -> 0 | H29: ='Resumen Costos'!H29 -> 0 | I29: =_xlfn.IFNA(C29/$J$1,0) -> 117.07426 | J29: =_xlfn.IFNA(D29/$J$1,0) -> 0 | K29: =_xlfn.IFNA(E29/$J$1,0) -> 405.17974 | L29: =_xlfn.IFNA(F29/$J$1,0) -> 564.80487 | M29: =_xlfn.IFNA(G29/$J$1,0) -> 0 | N29: =_xlfn.IFNA(H29/$J$1,0) -> 0 | O29: =_xlfn.IFNA(C29/$P$1,0) -> 131.70854 | P29: =_xlfn.IFNA(D29/$P$1,0) -> 0 | Q29: =_xlfn.IFNA(E29/$P$1,0) -> 455.82721 | R29: =_xlfn.IFNA(F29/$P$1,0) -> 635.40548 | S29: =_xlfn.IFNA(G29/$P$1,0) -> 0 | T29: =_xlfn.IFNA(H29/$P$1,0) -> 0 | U29: =_xlfn.IFNA(C29/$V$1,0) -> 150.52405 | V29: =_xlfn.IFNA(D29/$V$1,0) -> 0 | W29: =_xlfn.IFNA(E29/$V$1,0) -> 520.94538 | X29: =_xlfn.IFNA(F29/$V$1,0) -> 726.17769 | Y29: =_xlfn.IFNA(G29/$V$1,0) -> 0 | Z29: =_xlfn.IFNA(H29/$V$1,0) -> 0 | AA29: =_xlfn.IFNA(C29/$AB$1,0) -> 175.61139 | AB29: =_xlfn.IFNA(D29/$AB$1,0) -> 0 | AC29: =_xlfn.IFNA(E29/$AB$1,0) -> 607.76961 | AD29: =_xlfn.IFNA(F29/$AB$1,0) -> 847.20731 | AE29: =_xlfn.IFNA(G29/$AB$1,0) -> 0 | AF29: =_xlfn.IFNA(H29/$AB$1,0) -> 0 | AG29: 125 | AJ29: 590 | AM29: =_xlfn.IFNA(C29/$AN$1,0) -> 117.07426 | AN29: =_xlfn.IFNA(D29/$AN$1,0) -> 0 | AO29: =_xlfn.IFNA(E29/$AN$1,0) -> 405.17974 | AP29: =_xlfn.IFNA(F29/$AN$1,0) -> 564.80487 | AQ29: =_xlfn.IFNA(G29/$AN$1,0) -> 0 | AR29: =_xlfn.IFNA(H29/$AN$1,0) -> 0
B30: Brownie | C30: ='Resumen Costos'!C30 -> 45.518018 | D30: ='Resumen Costos'!D30 -> 0 | E30: ='Resumen Costos'!E30 -> 179.67515 | F30: ='Resumen Costos'!F30 -> 250.2993 | G30: ='Resumen Costos'!G30 -> 0 | H30: ='Resumen Costos'!H30 -> 0 | I30: =_xlfn.IFNA(C30/$J$1,0) -> 101.15115 | J30: =_xlfn.IFNA(D30/$J$1,0) -> 0 | K30: =_xlfn.IFNA(E30/$J$1,0) -> 399.2781 | L30: =_xlfn.IFNA(F30/$J$1,0) -> 556.22067 | M30: =_xlfn.IFNA(G30/$J$1,0) -> 0 | N30: =_xlfn.IFNA(H30/$J$1,0) -> 0 | O30: =_xlfn.IFNA(C30/$P$1,0) -> 113.79505 | P30: =_xlfn.IFNA(D30/$P$1,0) -> 0 | Q30: =_xlfn.IFNA(E30/$P$1,0) -> 449.18786 | R30: =_xlfn.IFNA(F30/$P$1,0) -> 625.74826 | S30: =_xlfn.IFNA(G30/$P$1,0) -> 0 | T30: =_xlfn.IFNA(H30/$P$1,0) -> 0 | U30: =_xlfn.IFNA(C30/$V$1,0) -> 130.05148 | V30: =_xlfn.IFNA(D30/$V$1,0) -> 0 | W30: =_xlfn.IFNA(E30/$V$1,0) -> 513.35756 | X30: =_xlfn.IFNA(F30/$V$1,0) -> 715.14087 | Y30: =_xlfn.IFNA(G30/$V$1,0) -> 0 | Z30: =_xlfn.IFNA(H30/$V$1,0) -> 0 | AA30: =_xlfn.IFNA(C30/$AB$1,0) -> 151.72673 | AB30: =_xlfn.IFNA(D30/$AB$1,0) -> 0 | AC30: =_xlfn.IFNA(E30/$AB$1,0) -> 598.91715 | AD30: =_xlfn.IFNA(F30/$AB$1,0) -> 834.33101 | AE30: =_xlfn.IFNA(G30/$AB$1,0) -> 0 | AF30: =_xlfn.IFNA(H30/$AB$1,0) -> 0 | AG30: 125 | AJ30: 560 | AM30: =_xlfn.IFNA(C30/$AN$1,0) -> 101.15115 | AN30: =_xlfn.IFNA(D30/$AN$1,0) -> 0 | AO30: =_xlfn.IFNA(E30/$AN$1,0) -> 399.2781 | AP30: =_xlfn.IFNA(F30/$AN$1,0) -> 556.22067 | AQ30: =_xlfn.IFNA(G30/$AN$1,0) -> 0 | AR30: =_xlfn.IFNA(H30/$AN$1,0) -> 0
B31: Zarzamora | C31: ='Resumen Costos'!C31 -> 52.866543 | D31: ='Resumen Costos'!D31 -> 0 | E31: ='Resumen Costos'!E31 -> 198.97726 | F31: ='Resumen Costos'!F31 -> 286.3147 | G31: ='Resumen Costos'!G31 -> 0 | H31: ='Resumen Costos'!H31 -> 0 | I31: =_xlfn.IFNA(C31/$J$1,0) -> 117.48121 | J31: =_xlfn.IFNA(D31/$J$1,0) -> 0 | K31: =_xlfn.IFNA(E31/$J$1,0) -> 442.1717 | L31: =_xlfn.IFNA(F31/$J$1,0) -> 636.25488 | M31: =_xlfn.IFNA(G31/$J$1,0) -> 0 | N31: =_xlfn.IFNA(H31/$J$1,0) -> 0 | O31: =_xlfn.IFNA(C31/$P$1,0) -> 132.16636 | P31: =_xlfn.IFNA(D31/$P$1,0) -> 0 | Q31: =_xlfn.IFNA(E31/$P$1,0) -> 497.44316 | R31: =_xlfn.IFNA(F31/$P$1,0) -> 715.78674 | S31: =_xlfn.IFNA(G31/$P$1,0) -> 0 | T31: =_xlfn.IFNA(H31/$P$1,0) -> 0 | U31: =_xlfn.IFNA(C31/$V$1,0) -> 151.04727 | V31: =_xlfn.IFNA(D31/$V$1,0) -> 0 | W31: =_xlfn.IFNA(E31/$V$1,0) -> 568.50647 | X31: =_xlfn.IFNA(F31/$V$1,0) -> 818.04199 | Y31: =_xlfn.IFNA(G31/$V$1,0) -> 0 | Z31: =_xlfn.IFNA(H31/$V$1,0) -> 0 | AA31: =_xlfn.IFNA(C31/$AB$1,0) -> 176.22181 | AB31: =_xlfn.IFNA(D31/$AB$1,0) -> 0 | AC31: =_xlfn.IFNA(E31/$AB$1,0) -> 663.25755 | AD31: =_xlfn.IFNA(F31/$AB$1,0) -> 954.38232 | AE31: =_xlfn.IFNA(G31/$AB$1,0) -> 0 | AF31: =_xlfn.IFNA(H31/$AB$1,0) -> 0 | AG31: 125 | AJ31: 650 | AM31: =_xlfn.IFNA(C31/$AN$1,0) -> 117.48121 | AN31: =_xlfn.IFNA(D31/$AN$1,0) -> 0 | AO31: =_xlfn.IFNA(E31/$AN$1,0) -> 442.1717 | AP31: =_xlfn.IFNA(F31/$AN$1,0) -> 636.25488 | AQ31: =_xlfn.IFNA(G31/$AN$1,0) -> 0 | AR31: =_xlfn.IFNA(H31/$AN$1,0) -> 0
